<?xml version="1.0" ?>
<!-- Generated using onshape-to-robot -->
<!-- Onshape https://cad.onshape.com/documents/93e40c2054094fd18d479553/w/e3a23b7dc09673b21c44fc8d/e/4147e7a6952b1ceabe18575a -->
<sdf version="1.7">
  <model name="omni_drive">
    <!-- Link chassis -->
    <link name="chassis">
      <inertial>
        <pose>-0.000747701 3.75549e-06 0.0125 0 0 0</pose>
        <mass>0.824729</mass>
        <inertia>
          <ixx>0.00213753</ixx>
          <ixy>-1.14179e-07</ixy>
          <ixz>0</ixz>
          <iyy>0.00211266</iyy>
          <iyz>0</iyz>
          <izz>0.00416427</izz>
        </inertia>
      </inertial>
      <pose>0 0 0 0 -0 0</pose>
      <!-- Part chassis_parts -->
      <visual name="chassis_parts_visual_mesh_1">
        <pose relative_to="chassis">-0.000747701 3.75549e-06 0.0125 0 -0 0</pose>
        <geometry>
          <mesh>
            <uri>package://ros_gz_omni_description/models/omni_drive/meshes/merged/chassis_visual.stl</uri>
          </mesh>
        </geometry>
        <material>
          <ambient>0.615686 0.811765 0.929412 1</ambient>
          <diffuse>0.615686 0.811765 0.929412 1</diffuse>
          <specular>0.1 0.1 0.1 1</specular>
          <emissive>0 0 0 0</emissive>
        </material>
      </visual>
    </link>
    <!-- Link assembly_4 -->
    <link name="assembly_4">
      <inertial>
        <pose>2.2358e-10 2.2358e-10 -0.0159948 0 0 0</pose>
        <mass>0.214734</mass>
        <inertia>
          <ixx>0.000156651</ixx>
          <ixy>3.45182e-14</ixy>
          <ixz>-5.70099e-12</ixz>
          <iyy>0.000156651</iyy>
          <iyz>5.70149e-12</iyz>
          <izz>0.000267711</izz>
        </inertia>
      </inertial>
      <pose relative_to="wheel_FR">0 0 0 0 -0 0</pose>
      <!-- Part assembly_4_parts -->
      <collision name="assembly_4_parts_collision_shapes_1">
        <pose relative_to="assembly_4">0 -2.1684e-17 -0.008 3.14159 -0 0</pose>
        <geometry>
          <cylinder>
            <length>0.01</length>
            <radius>0.0525</radius>
          </cylinder>
        </geometry>
        <surface>
          <friction>
            <ode>
              <mu>1.0</mu>
              <mu2>0.0</mu2>
              <fdir1 gz:expressed_in="chassis">1 1 0</fdir1>
            </ode>
          </friction>
        </surface>
      </collision>
      <collision name="assembly_4_parts_collision_shapes_2">
        <pose relative_to="assembly_4">0 -1.73472e-17 -0.024 0 -0 1.5708</pose>
        <geometry>
          <cylinder>
            <length>0.01</length>
            <radius>0.0525</radius>
          </cylinder>
        </geometry>
        <surface>
          <friction>
            <ode>
              <mu>1.0</mu>
              <mu2>0.0</mu2>
              <fdir1 gz:expressed_in="chassis">1 1 0</fdir1>
            </ode>
          </friction>
        </surface>
      </collision>
      <visual name="assembly_4_parts_visual_mesh_1">
        <pose relative_to="assembly_4">2.2358e-10 2.2358e-10 -0.0159948 1.5708 0.785398 1.5708</pose>
        <geometry>
          <mesh>
            <uri>package://ros_gz_omni_description/models/omni_drive/meshes/merged/assembly_4_visual.stl</uri>
          </mesh>
        </geometry>
        <material>
          <ambient>0.405267 0.405267 0.405267 1</ambient>
          <diffuse>0.405267 0.405267 0.405267 1</diffuse>
          <specular>0.1 0.1 0.1 1</specular>
          <emissive>0 0 0 0</emissive>
        </material>
      </visual>
    </link>
    <!-- Joint from chassis to assembly_4 -->
    <joint name="wheel_FR" type="revolute">
      <pose relative_to="chassis">0.0742462 -0.0742462 0.0125 -0.785398 -1.5708 0</pose>
      <parent>chassis</parent>
      <child>assembly_4</child>
      <axis>
        <xyz>0 0 1</xyz>
        <limit>
          <effort>10</effort>
          <velocity>10</velocity>
          <lower>-1.79769e+308</lower>
          <upper>1.79769e+308</upper>
        </limit>
        <dynamics>
          <friction>0.0</friction>
          <damping>0.0</damping>
        </dynamics>
      </axis>
    </joint>
    <!-- Link assembly_4_2 -->
    <link name="assembly_4_2">
      <inertial>
        <pose>2.2358e-10 2.2358e-10 -0.0159948 0 0 0</pose>
        <mass>0.214734</mass>
        <inertia>
          <ixx>0.000156651</ixx>
          <ixy>3.45182e-14</ixy>
          <ixz>-5.70099e-12</ixz>
          <iyy>0.000156651</iyy>
          <iyz>5.70149e-12</iyz>
          <izz>0.000267711</izz>
        </inertia>
      </inertial>
      <pose relative_to="wheel_FL">0 0 0 0 -0 0</pose>
      <!-- Part assembly_4_2_parts -->
      <collision name="assembly_4_2_parts_collision_shapes_1">
        <pose relative_to="assembly_4_2">0 -2.48303e-17 -0.008 3.14159 -0 0</pose>
        <geometry>
          <cylinder>
            <length>0.01</length>
            <radius>0.0525</radius>
          </cylinder>
        </geometry>
        <surface>
          <friction>
            <ode>
              <mu>1.0</mu>
              <mu2>0.0</mu2>
              <fdir1 gz:expressed_in="chassis">1 -1 0</fdir1>
            </ode>
          </friction>
        </surface>
      </collision>
      <collision name="assembly_4_2_parts_collision_shapes_2">
        <pose relative_to="assembly_4_2">0 -2.04935e-17 -0.024 0 -0 1.5708</pose>
        <geometry>
          <cylinder>
            <length>0.01</length>
            <radius>0.0525</radius>
          </cylinder>
        </geometry>
        <surface>
          <friction>
            <ode>
              <mu>1.0</mu>
              <mu2>0.0</mu2>
              <fdir1 gz:expressed_in="chassis">1 -1 0</fdir1>
            </ode>
          </friction>
        </surface>
      </collision>
      <visual name="assembly_4_2_parts_visual_mesh_1">
        <pose relative_to="assembly_4_2">2.2358e-10 2.2358e-10 -0.0159948 -1.5708 0.785398 -1.5708</pose>
        <geometry>
          <mesh>
            <uri>package://ros_gz_omni_description/models/omni_drive/meshes/merged/assembly_4_2_visual.stl</uri>
          </mesh>
        </geometry>
        <material>
          <ambient>0.405267 0.405267 0.405267 1</ambient>
          <diffuse>0.405267 0.405267 0.405267 1</diffuse>
          <specular>0.1 0.1 0.1 1</specular>
          <emissive>0 0 0 0</emissive>
        </material>
      </visual>
    </link>
    <!-- Joint from chassis to assembly_4_2 -->
    <joint name="wheel_FL" type="revolute">
      <pose relative_to="chassis">0.0742462 0.0742462 0.0125 0.785398 -1.5708 0</pose>
      <parent>chassis</parent>
      <child>assembly_4_2</child>
      <axis>
        <xyz>0 0 1</xyz>
        <limit>
          <effort>10</effort>
          <velocity>10</velocity>
          <lower>-1.79769e+308</lower>
          <upper>1.79769e+308</upper>
        </limit>
        <dynamics>
          <friction>0.0</friction>
          <damping>0.0</damping>
        </dynamics>
      </axis>
    </joint>
    <!-- Link assembly_4_3 -->
    <link name="assembly_4_3">
      <inertial>
        <pose>2.2358e-10 2.2358e-10 -0.0159948 0 0 0</pose>
        <mass>0.214734</mass>
        <inertia>
          <ixx>0.000156651</ixx>
          <ixy>3.45182e-14</ixy>
          <ixz>-5.70099e-12</ixz>
          <iyy>0.000156651</iyy>
          <iyz>5.70149e-12</iyz>
          <izz>0.000267711</izz>
        </inertia>
      </inertial>
      <pose relative_to="wheel_BR">0 0 0 0 -0 0</pose>
      <!-- Part assembly_4_3_parts -->
      <collision name="assembly_4_3_parts_collision_shapes_1">
        <pose relative_to="assembly_4_3">0 -1.00852e-17 -0.008 3.14159 -0 0</pose>
        <geometry>
          <cylinder>
            <length>0.01</length>
            <radius>0.0525</radius>
          </cylinder>
        </geometry>
        <surface>
          <friction>
            <ode>
              <mu>1.0</mu>
              <mu2>0.0</mu2>
              <fdir1 gz:expressed_in="chassis">1 -1 0</fdir1>
            </ode>
          </friction>
        </surface>
      </collision>
      <collision name="assembly_4_3_parts_collision_shapes_2">
        <pose relative_to="assembly_4_3">0 4.65997e-18 -0.024 0 -0 1.5708</pose>
        <geometry>
          <cylinder>
            <length>0.01</length>
            <radius>0.0525</radius>
          </cylinder>
        </geometry>
        <surface>
          <friction>
            <ode>
              <mu>1.0</mu>
              <mu2>0.0</mu2>
              <fdir1 gz:expressed_in="chassis">1 -1 0</fdir1>
            </ode>
          </friction>
        </surface>
      </collision>
      <visual name="assembly_4_3_parts_visual_mesh_1">
        <pose relative_to="assembly_4_3">2.2358e-10 2.2358e-10 -0.0159948 1.5708 -0.785398 1.5708</pose>
        <geometry>
          <mesh>
            <uri>package://ros_gz_omni_description/models/omni_drive/meshes/merged/assembly_4_3_visual.stl</uri>
          </mesh>
        </geometry>
        <material>
          <ambient>0.405267 0.405267 0.405267 1</ambient>
          <diffuse>0.405267 0.405267 0.405267 1</diffuse>
          <specular>0.1 0.1 0.1 1</specular>
          <emissive>0 0 0 0</emissive>
        </material>
      </visual>
    </link>
    <!-- Joint from chassis to assembly_4_3 -->
    <joint name="wheel_BR" type="revolute">
      <pose relative_to="chassis">-0.0742462 -0.0742462 0.0125 -2.35619 -1.5708 0</pose>
      <parent>chassis</parent>
      <child>assembly_4_3</child>
      <axis>
        <xyz>0 0 1</xyz>
        <limit>
          <effort>10</effort>
          <velocity>10</velocity>
          <lower>-1.79769e+308</lower>
          <upper>1.79769e+308</upper>
        </limit>
        <dynamics>
          <friction>0.0</friction>
          <damping>0.0</damping>
        </dynamics>
      </axis>
    </joint>
    <!-- Link assembly_4_4 -->
    <link name="assembly_4_4">
      <inertial>
        <pose>2.2358e-10 2.2358e-10 -0.0159948 0 0 0</pose>
        <mass>0.214734</mass>
        <inertia>
          <ixx>0.000156651</ixx>
          <ixy>3.45182e-14</ixy>
          <ixz>-5.70099e-12</ixz>
          <iyy>0.000156651</iyy>
          <iyz>5.70149e-12</iyz>
          <izz>0.000267711</izz>
        </inertia>
      </inertial>
      <pose relative_to="wheel_BL">0 0 0 0 -0 0</pose>
      <!-- Part assembly_4_4_parts -->
      <collision name="assembly_4_4_parts_collision_shapes_1">
        <pose relative_to="assembly_4_4">0 -7.80626e-18 -0.008 3.14159 -0 0</pose>
        <geometry>
          <cylinder>
            <length>0.01</length>
            <radius>0.0525</radius>
          </cylinder>
        </geometry>
        <surface>
          <friction>
            <ode>
              <mu>1.0</mu>
              <mu2>0.0</mu2>
              <fdir1 gz:expressed_in="chassis">1 1 0</fdir1>
            </ode>
          </friction>
        </surface>
      </collision>
      <collision name="assembly_4_4_parts_collision_shapes_2">
        <pose relative_to="assembly_4_4">0 6.07153e-18 -0.024 0 -0 1.5708</pose>
        <geometry>
          <cylinder>
            <length>0.01</length>
            <radius>0.0525</radius>
          </cylinder>
        </geometry>
        <surface>
          <friction>
            <ode>
              <mu>1.0</mu>
              <mu2>0.0</mu2>
              <fdir1 gz:expressed_in="chassis">1 1 0</fdir1>
            </ode>
          </friction>
        </surface>
      </collision>
      <visual name="assembly_4_4_parts_visual_mesh_1">
        <pose relative_to="assembly_4_4">2.2358e-10 2.2358e-10 -0.0159948 -1.5708 -0.785398 -1.5708</pose>
        <geometry>
          <mesh>
            <uri>package://ros_gz_omni_description/models/omni_drive/meshes/merged/assembly_4_4_visual.stl</uri>
          </mesh>
        </geometry>
        <material>
          <ambient>0.405267 0.405267 0.405267 1</ambient>
          <diffuse>0.405267 0.405267 0.405267 1</diffuse>
          <specular>0.1 0.1 0.1 1</specular>
          <emissive>0 0 0 0</emissive>
        </material>
      </visual>
    </link>
    <!-- Joint from chassis to assembly_4_4 -->
    <joint name="wheel_BL" type="revolute">
      <pose relative_to="chassis">-0.0742462 0.0742462 0.0125 2.35619 -1.5708 0</pose>
      <parent>chassis</parent>
      <child>assembly_4_4</child>
      <axis>
        <xyz>0 0 1</xyz>
        <limit>
          <effort>10</effort>
          <velocity>10</velocity>
          <lower>-1.79769e+308</lower>
          <upper>1.79769e+308</upper>
        </limit>
        <dynamics>
          <friction>0.0</friction>
          <damping>0.0</damping>
        </dynamics>
      </axis>
    </joint>
    <plugin filename="OmniDrive"
      name="ros_gz_omni_gazebo::OmniDrive">
      <front_left_joint>wheel_FL</front_left_joint>
      <front_right_joint>wheel_FR</front_right_joint>
      <back_left_joint>wheel_BL</back_left_joint>
      <back_right_joint>wheel_BR</back_right_joint>
      <wheel_separation>1</wheel_separation>
      <wheelbase>1</wheelbase>
      <wheel_radius>0.5</wheel_radius>
      <min_acceleration>-5</min_acceleration>
      <max_acceleration>5</max_acceleration>
    </plugin>
  </model>
</sdf>
