<?xml version="1.0" ?>
<!-- Generated using onshape-to-robot -->
<!-- Onshape https://cad.onshape.com/documents/93e40c2054094fd18d479553/w/e3a23b7dc09673b21c44fc8d/e/c24479ee078e1630aaf75236 -->
<robot name="omni_drive">
  <!-- Link part_1 -->
  <link name="part_1">
    <inertial>
      <origin xyz="-0.00053136 -0.000526049 0.0125" rpy="0 0 0"/>
      <mass value="0.824729"/>
      <inertia ixx="0.00212521" ixy="1.24365e-05" ixz="0" iyy="0.00212498" iyz="0" izz="0.00416427"/>
    </inertial>
    <!-- Part part_1 -->
    <visual>
      <origin xyz="0 0 0" rpy="0 -0 0"/>
      <geometry>
        <mesh filename="package://meshes/part_1.stl"/>
      </geometry>
      <material name="part_1_material">
        <color rgba="0.615686 0.811765 0.929412 1"/>
      </material>
    </visual>
    <collision>
      <origin xyz="0 0 0" rpy="0 -0 0"/>
      <geometry>
        <mesh filename="package://meshes/part_1.stl"/>
      </geometry>
    </collision>
  </link>
  <!-- Frame omni_drive (dummy link + fixed joint) -->
  <link name="omni_drive">
    <origin xyz="0 0 0" rpy="0 -0 0"/>
    <inertial>
      <origin xyz="0 0 0" rpy="0 0 0"/>
      <mass value="1e-9"/>
      <inertia ixx="0" ixy="0" ixz="0" iyy="0" iyz="0" izz="0"/>
    </inertial>
  </link>
  <joint name="omni_drive_frame" type="fixed">
    <origin xyz="-0.00053136 -0.000526049 0.025" rpy="0 -0 0.785398"/>
    <parent link="part_1"/>
    <child link="omni_drive"/>
    <axis xyz="0 0 0"/>
  </joint>
  <!-- Link wheel4_shaft_holder_v2 -->
  <link name="wheel4_shaft_holder_v2">
    <inertial>
      <origin xyz="3.57044e-13 3.57055e-13 0.0159932" rpy="0 0 0"/>
      <mass value="0.162524"/>
      <inertia ixx="0.000106018" ixy="-9.74088e-21" ixz="-4.58452e-15" iyy="0.000106018" iyz="-5.68705e-15" izz="0.000180425"/>
    </inertial>
    <!-- Part wheel4_body_omni_v4 -->
    <visual>
      <origin xyz="-1.73472e-17 1.87928e-17 0.032" rpy="-3.38788e-16 1.5708 0"/>
      <geometry>
        <mesh filename="package://meshes/wheel4_body_omni_v4.stl"/>
      </geometry>
      <material name="wheel4_body_omni_v4_material">
        <color rgba="0.627451 0.627451 0.627451 1"/>
      </material>
    </visual>
    <!-- Part wheel4_shaft_omni_v1 -->
    <!-- Part wheel4_shaft_omni_v1_2 -->
    <!-- Part wheel4_shaft_omni_v1_3 -->
    <!-- Part wheel4_shaft_holder_v2 -->
    <visual>
      <origin xyz="0 -2.02384e-18 0.013" rpy="1.5708 -1.5708 0"/>
      <geometry>
        <mesh filename="package://meshes/wheel4_shaft_holder_v2.stl"/>
      </geometry>
      <material name="wheel4_shaft_holder_v2_material">
        <color rgba="0.627451 0.627451 0.627451 1"/>
      </material>
    </visual>
    <!-- Part wheel4_shaft_omni_v1_4 -->
    <!-- Part wheel4_shaft_omni_v1_5 -->
    <!-- Part wheel4_shaft_omni_v1_6 -->
    <!-- Part wheel4_shaft_omni_v1_7 -->
    <!-- Part wheel4_shaft_omni_v1_8 -->
    <!-- Part wheel4_shaft_omni_v1_9 -->
    <!-- Part wheel4_shaft_omni_v1_10 -->
    <!-- Part wheel4_shaft_omni_v1_11 -->
    <!-- Part wheel4_shaft_omni_v1_12 -->
    <!-- Part wheel4_shaft_omni_v1_13 -->
    <!-- Part wheel4_shaft_omni_v1_14 -->
    <!-- Part wheel4_shaft_omni_v1_15 -->
    <!-- Part wheel4_body_omni_v4_2 -->
    <visual>
      <origin xyz="0 0 0.013" rpy="1.5708 1.5708 0"/>
      <geometry>
        <mesh filename="package://meshes/wheel4_body_omni_v4__2.stl"/>
      </geometry>
      <material name="wheel4_body_omni_v4_2_material">
        <color rgba="0.627451 0.627451 0.627451 1"/>
      </material>
    </visual>
    <!-- Part wheel4_shaft_omni_v1_16 -->
    <!-- Part wheel4_shaft_omni_v1_17 -->
    <!-- Part wheel4_shaft_omni_v1_18 -->
    <!-- Part wheel4_shaft_omni_v1_19 -->
    <!-- Part wheel4_shaft_omni_v1_20 -->
  </link>
  <!-- Frame motorC (dummy link + fixed joint) -->
  <link name="motorC">
    <origin xyz="0 0 0" rpy="0 -0 0"/>
    <inertial>
      <origin xyz="0 0 0" rpy="0 0 0"/>
      <mass value="1e-9"/>
      <inertia ixx="0" ixy="0" ixz="0" iyy="0" iyz="0" izz="0"/>
    </inertial>
  </link>
  <joint name="motorC_frame" type="fixed">
    <origin xyz="0 3.37024e-19 0" rpy="-2.36658e-30 1.63005e-32 -1.5708"/>
    <parent link="wheel4_shaft_holder_v2"/>
    <child link="motorC"/>
    <axis xyz="0 0 0"/>
  </joint>
  <!-- Link wheel4_omniwheel_tyre_v1 -->
  <link name="wheel4_omniwheel_tyre_v1">
    <inertial>
      <origin xyz="-6.93633e-10 5.993e-19 1.35567e-09" rpy="0 0 0"/>
      <mass value="0.00502735"/>
      <inertia ixx="2.29535e-07" ixy="1.27418e-23" ixz="8.11134e-13" iyy="2.29535e-07" iyz="6.3587e-26" izz="2.32706e-07"/>
    </inertial>
    <!-- Part wheel4_omniwheel_tyre_v1 -->
    <visual>
      <origin xyz="1.38778e-17 0 0.01625" rpy="1.5708 5.20093e-17 -5.55112e-17"/>
      <geometry>
        <mesh filename="package://meshes/wheel4_omniwheel_tyre_v1.stl"/>
      </geometry>
      <material name="wheel4_omniwheel_tyre_v1_material">
        <color rgba="0.152941 0.152941 0.152941 1"/>
      </material>
    </visual>
    <collision>
      <origin xyz="1.38778e-17 0 0.01625" rpy="1.5708 5.20093e-17 -5.55112e-17"/>
      <geometry>
        <mesh filename="package://meshes/wheel4_omniwheel_tyre_v1.stl"/>
      </geometry>
    </collision>
  </link>
  <!-- Joint from wheel4_shaft_holder_v2 to wheel4_omniwheel_tyre_v1 -->
  <joint name="wheel_3k" type="continuous">
    <origin xyz="-0.0403869 2.57317e-17 0.0255" rpy="1.5708 0.992087 -3.14159"/>
    <parent link="wheel4_shaft_holder_v2"/>
    <child link="wheel4_omniwheel_tyre_v1"/>
    <axis xyz="0 0 1"/>
    <limit effort="5" velocity="10"/>
    <joint_properties friction="0.1"/>
  </joint>
  <!-- Link wheel4_omniwheel_tyre_v1_2 -->
  <link name="wheel4_omniwheel_tyre_v1_2">
    <inertial>
      <origin xyz="-6.93633e-10 9.25426e-19 1.35567e-09" rpy="0 0 0"/>
      <mass value="0.00502735"/>
      <inertia ixx="2.29535e-07" ixy="6.37087e-23" ixz="8.11134e-13" iyy="2.29535e-07" iyz="-6.37074e-24" izz="2.32706e-07"/>
    </inertial>
    <!-- Part wheel4_omniwheel_tyre_v1_2 -->
    <visual>
      <origin xyz="1.38778e-17 0 0.01625" rpy="1.5708 5.55112e-17 1.66533e-16"/>
      <geometry>
        <mesh filename="package://meshes/wheel4_omniwheel_tyre_v1.stl"/>
      </geometry>
      <material name="wheel4_omniwheel_tyre_v1_2_material">
        <color rgba="0.152941 0.152941 0.152941 1"/>
      </material>
    </visual>
    <collision>
      <origin xyz="1.38778e-17 0 0.01625" rpy="1.5708 5.55112e-17 1.66533e-16"/>
      <geometry>
        <mesh filename="package://meshes/wheel4_omniwheel_tyre_v1.stl"/>
      </geometry>
    </collision>
  </link>
  <!-- Joint from wheel4_shaft_holder_v2 to wheel4_omniwheel_tyre_v1_2 -->
  <joint name="wheel_3l" type="continuous">
    <origin xyz="-0.0326737 0.0237388 0.0255" rpy="-1.5708 -0.508017 -0.628319"/>
    <parent link="wheel4_shaft_holder_v2"/>
    <child link="wheel4_omniwheel_tyre_v1_2"/>
    <axis xyz="0 0 1"/>
    <limit effort="5" velocity="10"/>
    <joint_properties friction="0.1"/>
  </joint>
  <!-- Link wheel4_omniwheel_tyre_v1_3 -->
  <link name="wheel4_omniwheel_tyre_v1_3">
    <inertial>
      <origin xyz="-6.93633e-10 -2.72248e-17 1.35567e-09" rpy="0 0 0"/>
      <mass value="0.00502735"/>
      <inertia ixx="2.29535e-07" ixy="1.59274e-24" ixz="8.11134e-13" iyy="2.29535e-07" iyz="8.73362e-25" izz="2.32706e-07"/>
    </inertial>
    <!-- Part wheel4_omniwheel_tyre_v1_3 -->
    <visual>
      <origin xyz="3.46945e-18 -2.77556e-17 0.01625" rpy="1.5708 5.55112e-17 8.67362e-19"/>
      <geometry>
        <mesh filename="package://meshes/wheel4_omniwheel_tyre_v1.stl"/>
      </geometry>
      <material name="wheel4_omniwheel_tyre_v1_3_material">
        <color rgba="0.152941 0.152941 0.152941 1"/>
      </material>
    </visual>
    <collision>
      <origin xyz="3.46945e-18 -2.77556e-17 0.01625" rpy="1.5708 5.55112e-17 8.67362e-19"/>
      <geometry>
        <mesh filename="package://meshes/wheel4_omniwheel_tyre_v1.stl"/>
      </geometry>
    </collision>
  </link>
  <!-- Joint from wheel4_shaft_holder_v2 to wheel4_omniwheel_tyre_v1_3 -->
  <joint name="wheel_3m" type="continuous">
    <origin xyz="-0.0124802 0.0384102 0.0255" rpy="-1.5708 -0.0501607 -1.25664"/>
    <parent link="wheel4_shaft_holder_v2"/>
    <child link="wheel4_omniwheel_tyre_v1_3"/>
    <axis xyz="0 0 1"/>
    <limit effort="5" velocity="10"/>
    <joint_properties friction="0.1"/>
  </joint>
  <!-- Link wheel4_omniwheel_tyre_v1_4 -->
  <link name="wheel4_omniwheel_tyre_v1_4">
    <inertial>
      <origin xyz="-6.93633e-10 -5.49804e-17 1.35567e-09" rpy="0 0 0"/>
      <mass value="0.00502735"/>
      <inertia ixx="2.29535e-07" ixy="-1.9907e-25" ixz="8.11134e-13" iyy="2.29535e-07" iyz="8.73359e-25" izz="2.32706e-07"/>
    </inertial>
    <!-- Part wheel4_omniwheel_tyre_v1_4 -->
    <visual>
      <origin xyz="0 -5.55112e-17 0.01625" rpy="1.5708 5.55112e-17 -2.60209e-18"/>
      <geometry>
        <mesh filename="package://meshes/wheel4_omniwheel_tyre_v1.stl"/>
      </geometry>
      <material name="wheel4_omniwheel_tyre_v1_4_material">
        <color rgba="0.152941 0.152941 0.152941 1"/>
      </material>
    </visual>
    <collision>
      <origin xyz="0 -5.55112e-17 0.01625" rpy="1.5708 5.55112e-17 -2.60209e-18"/>
      <geometry>
        <mesh filename="package://meshes/wheel4_omniwheel_tyre_v1.stl"/>
      </geometry>
    </collision>
  </link>
  <!-- Joint from wheel4_shaft_holder_v2 to wheel4_omniwheel_tyre_v1_4 -->
  <joint name="wheel_3n" type="continuous">
    <origin xyz="0.0124802 0.0384102 0.0255" rpy="1.5708 -0.0501607 -1.88496"/>
    <parent link="wheel4_shaft_holder_v2"/>
    <child link="wheel4_omniwheel_tyre_v1_4"/>
    <axis xyz="0 0 1"/>
    <limit effort="5" velocity="10"/>
    <joint_properties friction="0.1"/>
  </joint>
  <!-- Link wheel4_omniwheel_tyre_v1_5 -->
  <link name="wheel4_omniwheel_tyre_v1_5">
    <inertial>
      <origin xyz="-6.93633e-10 -4.27658e-19 1.35567e-09" rpy="0 0 0"/>
      <mass value="0.00502735"/>
      <inertia ixx="2.29535e-07" ixy="-5.09669e-23" ixz="8.11134e-13" iyy="2.29535e-07" iyz="6.63479e-24" izz="2.32706e-07"/>
    </inertial>
    <!-- Part wheel4_omniwheel_tyre_v1_5 -->
    <visual>
      <origin xyz="3.46945e-18 0 0.01625" rpy="1.5708 -5.55112e-17 -1.11022e-16"/>
      <geometry>
        <mesh filename="package://meshes/wheel4_omniwheel_tyre_v1.stl"/>
      </geometry>
      <material name="wheel4_omniwheel_tyre_v1_5_material">
        <color rgba="0.152941 0.152941 0.152941 1"/>
      </material>
    </visual>
    <collision>
      <origin xyz="3.46945e-18 0 0.01625" rpy="1.5708 -5.55112e-17 -1.11022e-16"/>
      <geometry>
        <mesh filename="package://meshes/wheel4_omniwheel_tyre_v1.stl"/>
      </geometry>
    </collision>
  </link>
  <!-- Joint from wheel4_shaft_holder_v2 to wheel4_omniwheel_tyre_v1_5 -->
  <joint name="wheel_3o" type="continuous">
    <origin xyz="0.0326737 0.0237388 0.0255" rpy="1.5708 -0.508017 -2.51327"/>
    <parent link="wheel4_shaft_holder_v2"/>
    <child link="wheel4_omniwheel_tyre_v1_5"/>
    <axis xyz="0 0 1"/>
    <limit effort="5" velocity="10"/>
    <joint_properties friction="0.1"/>
  </joint>
  <!-- Link wheel4_omniwheel_tyre_v1_6 -->
  <link name="wheel4_omniwheel_tyre_v1_6">
    <inertial>
      <origin xyz="-6.93633e-10 7.53819e-18 1.35567e-09" rpy="0 0 0"/>
      <mass value="0.00502735"/>
      <inertia ixx="2.29535e-07" ixy="1.27418e-23" ixz="8.11134e-13" iyy="2.29535e-07" iyz="6.3587e-26" izz="2.32706e-07"/>
    </inertial>
    <!-- Part wheel4_omniwheel_tyre_v1_6 -->
    <visual>
      <origin xyz="2.77556e-17 6.93889e-18 0.01625" rpy="1.5708 5.20093e-17 -5.55112e-17"/>
      <geometry>
        <mesh filename="package://meshes/wheel4_omniwheel_tyre_v1.stl"/>
      </geometry>
      <material name="wheel4_omniwheel_tyre_v1_6_material">
        <color rgba="0.152941 0.152941 0.152941 1"/>
      </material>
    </visual>
    <collision>
      <origin xyz="2.77556e-17 6.93889e-18 0.01625" rpy="1.5708 5.20093e-17 -5.55112e-17"/>
      <geometry>
        <mesh filename="package://meshes/wheel4_omniwheel_tyre_v1.stl"/>
      </geometry>
    </collision>
  </link>
  <!-- Joint from wheel4_shaft_holder_v2 to wheel4_omniwheel_tyre_v1_6 -->
  <joint name="wheel_3p" type="continuous">
    <origin xyz="0.0403869 2.92012e-17 0.0255" rpy="1.5708 0.992087 -3.14159"/>
    <parent link="wheel4_shaft_holder_v2"/>
    <child link="wheel4_omniwheel_tyre_v1_6"/>
    <axis xyz="0 0 1"/>
    <limit effort="5" velocity="10"/>
    <joint_properties friction="0.1"/>
  </joint>
  <!-- Link wheel4_omniwheel_tyre_v1_7 -->
  <link name="wheel4_omniwheel_tyre_v1_7">
    <inertial>
      <origin xyz="-6.93633e-10 2.823e-17 1.35567e-09" rpy="0 0 0"/>
      <mass value="0.00502735"/>
      <inertia ixx="2.29535e-07" ixy="1.27418e-23" ixz="8.11134e-13" iyy="2.29535e-07" iyz="1.28297e-23" izz="2.32706e-07"/>
    </inertial>
    <!-- Part wheel4_omniwheel_tyre_v1_7 -->
    <visual>
      <origin xyz="-1.38778e-17 2.77556e-17 0.01625" rpy="1.5708 -5.55112e-17 0"/>
      <geometry>
        <mesh filename="package://meshes/wheel4_omniwheel_tyre_v1.stl"/>
      </geometry>
      <material name="wheel4_omniwheel_tyre_v1_7_material">
        <color rgba="0.152941 0.152941 0.152941 1"/>
      </material>
    </visual>
    <collision>
      <origin xyz="-1.38778e-17 2.77556e-17 0.01625" rpy="1.5708 -5.55112e-17 0"/>
      <geometry>
        <mesh filename="package://meshes/wheel4_omniwheel_tyre_v1.stl"/>
      </geometry>
    </collision>
  </link>
  <!-- Joint from wheel4_shaft_holder_v2 to wheel4_omniwheel_tyre_v1_7 -->
  <joint name="wheel_3q" type="continuous">
    <origin xyz="0.0326737 -0.0237388 0.0255" rpy="-1.5708 -0.508017 -0.628319"/>
    <parent link="wheel4_shaft_holder_v2"/>
    <child link="wheel4_omniwheel_tyre_v1_7"/>
    <axis xyz="0 0 1"/>
    <limit effort="5" velocity="10"/>
    <joint_properties friction="0.1"/>
  </joint>
  <!-- Link wheel4_omniwheel_tyre_v1_8 -->
  <link name="wheel4_omniwheel_tyre_v1_8">
    <inertial>
      <origin xyz="-6.93633e-10 -1.43054e-17 1.35567e-09" rpy="0 0 0"/>
      <mass value="0.00502735"/>
      <inertia ixx="2.29535e-07" ixy="-1.27417e-23" ixz="8.11134e-13" iyy="2.29535e-07" iyz="1.93766e-23" izz="2.32706e-07"/>
    </inertial>
    <!-- Part wheel4_omniwheel_tyre_v1_8 -->
    <visual>
      <origin xyz="-1.38778e-17 -1.38778e-17 0.01625" rpy="1.5708 5.55112e-17 6.93889e-18"/>
      <geometry>
        <mesh filename="package://meshes/wheel4_omniwheel_tyre_v1.stl"/>
      </geometry>
      <material name="wheel4_omniwheel_tyre_v1_8_material">
        <color rgba="0.152941 0.152941 0.152941 1"/>
      </material>
    </visual>
    <collision>
      <origin xyz="-1.38778e-17 -1.38778e-17 0.01625" rpy="1.5708 5.55112e-17 6.93889e-18"/>
      <geometry>
        <mesh filename="package://meshes/wheel4_omniwheel_tyre_v1.stl"/>
      </geometry>
    </collision>
  </link>
  <!-- Joint from wheel4_shaft_holder_v2 to wheel4_omniwheel_tyre_v1_8 -->
  <joint name="wheel_3r" type="continuous">
    <origin xyz="0.0124802 -0.0384102 0.0255" rpy="-1.5708 -0.614515 -1.25664"/>
    <parent link="wheel4_shaft_holder_v2"/>
    <child link="wheel4_omniwheel_tyre_v1_8"/>
    <axis xyz="0 0 1"/>
    <limit effort="5" velocity="10"/>
    <joint_properties friction="0.1"/>
  </joint>
  <!-- Link wheel4_omniwheel_tyre_v1_9 -->
  <link name="wheel4_omniwheel_tyre_v1_9">
    <inertial>
      <origin xyz="-6.93633e-10 -2.72248e-17 1.35567e-09" rpy="0 0 0"/>
      <mass value="0.00502735"/>
      <inertia ixx="2.29535e-07" ixy="-3.9816e-25" ixz="8.11134e-13" iyy="2.29535e-07" iyz="1.27154e-24" izz="2.32706e-07"/>
    </inertial>
    <!-- Part wheel4_omniwheel_tyre_v1_9 -->
    <visual>
      <origin xyz="0 -2.77556e-17 0.01625" rpy="1.5708 5.55112e-17 2.60209e-18"/>
      <geometry>
        <mesh filename="package://meshes/wheel4_omniwheel_tyre_v1.stl"/>
      </geometry>
      <material name="wheel4_omniwheel_tyre_v1_9_material">
        <color rgba="0.152941 0.152941 0.152941 1"/>
      </material>
    </visual>
    <collision>
      <origin xyz="0 -2.77556e-17 0.01625" rpy="1.5708 5.55112e-17 2.60209e-18"/>
      <geometry>
        <mesh filename="package://meshes/wheel4_omniwheel_tyre_v1.stl"/>
      </geometry>
    </collision>
  </link>
  <!-- Joint from wheel4_shaft_holder_v2 to wheel4_omniwheel_tyre_v1_9 -->
  <joint name="wheel_3s" type="continuous">
    <origin xyz="-0.0124802 -0.0384102 0.0255" rpy="1.5708 -0.0501607 -1.88496"/>
    <parent link="wheel4_shaft_holder_v2"/>
    <child link="wheel4_omniwheel_tyre_v1_9"/>
    <axis xyz="0 0 1"/>
    <limit effort="5" velocity="10"/>
    <joint_properties friction="0.1"/>
  </joint>
  <!-- Link wheel4_omniwheel_tyre_v1_10 -->
  <link name="wheel4_omniwheel_tyre_v1_10">
    <inertial>
      <origin xyz="-6.93633e-10 1.39012e-17 1.35567e-09" rpy="0 0 0"/>
      <mass value="0.00502735"/>
      <inertia ixx="2.29535e-07" ixy="4.5027e-29" ixz="8.11134e-13" iyy="2.29535e-07" iyz="1.29178e-23" izz="2.32706e-07"/>
    </inertial>
    <!-- Part wheel4_omniwheel_tyre_v1_10 -->
    <visual>
      <origin xyz="-1.38778e-17 1.38778e-17 0.01625" rpy="1.5708 -0 0"/>
      <geometry>
        <mesh filename="package://meshes/wheel4_omniwheel_tyre_v1.stl"/>
      </geometry>
      <material name="wheel4_omniwheel_tyre_v1_10_material">
        <color rgba="0.152941 0.152941 0.152941 1"/>
      </material>
    </visual>
    <collision>
      <origin xyz="-1.38778e-17 1.38778e-17 0.01625" rpy="1.5708 -0 0"/>
      <geometry>
        <mesh filename="package://meshes/wheel4_omniwheel_tyre_v1.stl"/>
      </geometry>
    </collision>
  </link>
  <!-- Joint from wheel4_shaft_holder_v2 to wheel4_omniwheel_tyre_v1_10 -->
  <joint name="wheel_3t" type="continuous">
    <origin xyz="-0.0326737 -0.0237388 0.0255" rpy="1.5708 -0.508017 -2.51327"/>
    <parent link="wheel4_shaft_holder_v2"/>
    <child link="wheel4_omniwheel_tyre_v1_10"/>
    <axis xyz="0 0 1"/>
    <limit effort="5" velocity="10"/>
    <joint_properties friction="0.1"/>
  </joint>
  <!-- Link wheel4_omniwheel_tyre_v1_11 -->
  <link name="wheel4_omniwheel_tyre_v1_11">
    <inertial>
      <origin xyz="-6.93633e-10 1.34034e-17 -1.46309e-09" rpy="0 0 0"/>
      <mass value="0.00502735"/>
      <inertia ixx="2.29535e-07" ixy="1.27417e-23" ixz="-8.11134e-13" iyy="2.29535e-07" iyz="-6.28292e-24" izz="2.32706e-07"/>
    </inertial>
    <!-- Part wheel4_omniwheel_tyre_v1_11 -->
    <visual>
      <origin xyz="0 1.38778e-17 -0.01625" rpy="-1.5708 -0 5.55112e-17"/>
      <geometry>
        <mesh filename="package://meshes/wheel4_omniwheel_tyre_v1.stl"/>
      </geometry>
      <material name="wheel4_omniwheel_tyre_v1_11_material">
        <color rgba="0.152941 0.152941 0.152941 1"/>
      </material>
    </visual>
    <collision>
      <origin xyz="0 1.38778e-17 -0.01625" rpy="-1.5708 -0 5.55112e-17"/>
      <geometry>
        <mesh filename="package://meshes/wheel4_omniwheel_tyre_v1.stl"/>
      </geometry>
    </collision>
  </link>
  <!-- Joint from wheel4_shaft_holder_v2 to wheel4_omniwheel_tyre_v1_11 -->
  <joint name="wheel_3j" type="continuous">
    <origin xyz="0.0384102 0.0124802 0.0065" rpy="1.5708 -0.971379 -2.82743"/>
    <parent link="wheel4_shaft_holder_v2"/>
    <child link="wheel4_omniwheel_tyre_v1_11"/>
    <axis xyz="0 0 1"/>
    <limit effort="5" velocity="10"/>
    <joint_properties friction="0.1"/>
  </joint>
  <!-- Link wheel4_omniwheel_tyre_v1_12 -->
  <link name="wheel4_omniwheel_tyre_v1_12">
    <inertial>
      <origin xyz="-6.93633e-10 2.823e-17 1.35567e-09" rpy="0 0 0"/>
      <mass value="0.00502735"/>
      <inertia ixx="2.29535e-07" ixy="6.3709e-24" ixz="8.11134e-13" iyy="2.29535e-07" iyz="9.6443e-24" izz="2.32706e-07"/>
    </inertial>
    <!-- Part wheel4_omniwheel_tyre_v1_12 -->
    <visual>
      <origin xyz="-3.46945e-18 2.77556e-17 0.01625" rpy="1.5708 -1.11022e-16 -1.38778e-17"/>
      <geometry>
        <mesh filename="package://meshes/wheel4_omniwheel_tyre_v1.stl"/>
      </geometry>
      <material name="wheel4_omniwheel_tyre_v1_12_material">
        <color rgba="0.152941 0.152941 0.152941 1"/>
      </material>
    </visual>
    <collision>
      <origin xyz="-3.46945e-18 2.77556e-17 0.01625" rpy="1.5708 -1.11022e-16 -1.38778e-17"/>
      <geometry>
        <mesh filename="package://meshes/wheel4_omniwheel_tyre_v1.stl"/>
      </geometry>
    </collision>
  </link>
  <!-- Joint from wheel4_shaft_holder_v2 to wheel4_omniwheel_tyre_v1_12 -->
  <joint name="wheel_3i" type="continuous">
    <origin xyz="0.0237388 0.0326737 0.0065" rpy="-1.5708 -0.210366 -2.19911"/>
    <parent link="wheel4_shaft_holder_v2"/>
    <child link="wheel4_omniwheel_tyre_v1_12"/>
    <axis xyz="0 0 1"/>
    <limit effort="5" velocity="10"/>
    <joint_properties friction="0.1"/>
  </joint>
  <!-- Link wheel4_omniwheel_tyre_v1_13 -->
  <link name="wheel4_omniwheel_tyre_v1_13">
    <inertial>
      <origin xyz="-2.36344e-17 6.93633e-10 1.35567e-09" rpy="0 0 0"/>
      <mass value="0.00502735"/>
      <inertia ixx="2.29535e-07" ixy="-5.33202e-28" ixz="2.08372e-24" iyy="2.29535e-07" iyz="-8.11134e-13" izz="2.32706e-07"/>
    </inertial>
    <!-- Part wheel4_omniwheel_tyre_v1_13 -->
    <visual>
      <origin xyz="-1.38778e-17 -2.77556e-17 0.01625" rpy="1.5708 1.57747e-15 -1.5708"/>
      <geometry>
        <mesh filename="package://meshes/wheel4_omniwheel_tyre_v1.stl"/>
      </geometry>
      <material name="wheel4_omniwheel_tyre_v1_13_material">
        <color rgba="0.152941 0.152941 0.152941 1"/>
      </material>
    </visual>
    <collision>
      <origin xyz="-1.38778e-17 -2.77556e-17 0.01625" rpy="1.5708 1.57747e-15 -1.5708"/>
      <geometry>
        <mesh filename="package://meshes/wheel4_omniwheel_tyre_v1.stl"/>
      </geometry>
    </collision>
  </link>
  <!-- Joint from wheel4_shaft_holder_v2 to wheel4_omniwheel_tyre_v1_13 -->
  <joint name="wheel_3h" type="continuous">
    <origin xyz="0 0.0403869 0.0065" rpy="-4.44089e-16 1.5708 0"/>
    <parent link="wheel4_shaft_holder_v2"/>
    <child link="wheel4_omniwheel_tyre_v1_13"/>
    <axis xyz="0 0 1"/>
    <limit effort="5" velocity="10"/>
    <joint_properties friction="0.1"/>
  </joint>
  <!-- Link wheel4_omniwheel_tyre_v1_14 -->
  <link name="wheel4_omniwheel_tyre_v1_14">
    <inertial>
      <origin xyz="-6.93633e-10 1.15094e-18 1.35567e-09" rpy="0 0 0"/>
      <mass value="0.00502735"/>
      <inertia ixx="2.29535e-07" ixy="6.37086e-24" ixz="8.11134e-13" iyy="2.29535e-07" iyz="-3.2294e-24" izz="2.32706e-07"/>
    </inertial>
    <!-- Part wheel4_omniwheel_tyre_v1_14 -->
    <visual>
      <origin xyz="0 0 0.01625" rpy="1.5708 -0 4.16334e-17"/>
      <geometry>
        <mesh filename="package://meshes/wheel4_omniwheel_tyre_v1.stl"/>
      </geometry>
      <material name="wheel4_omniwheel_tyre_v1_14_material">
        <color rgba="0.152941 0.152941 0.152941 1"/>
      </material>
    </visual>
    <collision>
      <origin xyz="0 0 0.01625" rpy="1.5708 -0 4.16334e-17"/>
      <geometry>
        <mesh filename="package://meshes/wheel4_omniwheel_tyre_v1.stl"/>
      </geometry>
    </collision>
  </link>
  <!-- Joint from wheel4_shaft_holder_v2 to wheel4_omniwheel_tyre_v1_14 -->
  <joint name="wheel_3g" type="continuous">
    <origin xyz="-0.0237388 0.0326737 0.0065" rpy="-1.5708 -0.210366 -0.942478"/>
    <parent link="wheel4_shaft_holder_v2"/>
    <child link="wheel4_omniwheel_tyre_v1_14"/>
    <axis xyz="0 0 1"/>
    <limit effort="5" velocity="10"/>
    <joint_properties friction="0.1"/>
  </joint>
  <!-- Link wheel4_omniwheel_tyre_v1_15 -->
  <link name="wheel4_omniwheel_tyre_v1_15">
    <inertial>
      <origin xyz="-6.93633e-10 1.52542e-17 1.35567e-09" rpy="0 0 0"/>
      <mass value="0.00502735"/>
      <inertia ixx="2.29535e-07" ixy="1.27417e-23" ixz="8.11134e-13" iyy="2.29535e-07" iyz="1.90245e-23" izz="2.32706e-07"/>
    </inertial>
    <!-- Part wheel4_omniwheel_tyre_v1_15 -->
    <visual>
      <origin xyz="0 1.38778e-17 0.01625" rpy="1.5708 5.55112e-17 -1.11022e-16"/>
      <geometry>
        <mesh filename="package://meshes/wheel4_omniwheel_tyre_v1.stl"/>
      </geometry>
      <material name="wheel4_omniwheel_tyre_v1_15_material">
        <color rgba="0.152941 0.152941 0.152941 1"/>
      </material>
    </visual>
    <collision>
      <origin xyz="0 1.38778e-17 0.01625" rpy="1.5708 5.55112e-17 -1.11022e-16"/>
      <geometry>
        <mesh filename="package://meshes/wheel4_omniwheel_tyre_v1.stl"/>
      </geometry>
    </collision>
  </link>
  <!-- Joint from wheel4_shaft_holder_v2 to wheel4_omniwheel_tyre_v1_15 -->
  <joint name="wheel_3f" type="continuous">
    <origin xyz="-0.0384102 0.0124802 0.0065" rpy="-1.5708 -0.990694 -0.314159"/>
    <parent link="wheel4_shaft_holder_v2"/>
    <child link="wheel4_omniwheel_tyre_v1_15"/>
    <axis xyz="0 0 1"/>
    <limit effort="5" velocity="10"/>
    <joint_properties friction="0.1"/>
  </joint>
  <!-- Link wheel4_omniwheel_tyre_v1_16 -->
  <link name="wheel4_omniwheel_tyre_v1_16">
    <inertial>
      <origin xyz="-6.93633e-10 -6.91552e-18 1.35567e-09" rpy="0 0 0"/>
      <mass value="0.00502735"/>
      <inertia ixx="2.29535e-07" ixy="-2.54834e-23" ixz="8.11134e-13" iyy="2.29535e-07" iyz="1.29178e-23" izz="2.32706e-07"/>
    </inertial>
    <!-- Part wheel4_omniwheel_tyre_v1_16 -->
    <visual>
      <origin xyz="2.77556e-17 -6.93889e-18 0.01625" rpy="1.5708 5.55112e-17 0"/>
      <geometry>
        <mesh filename="package://meshes/wheel4_omniwheel_tyre_v1.stl"/>
      </geometry>
      <material name="wheel4_omniwheel_tyre_v1_16_material">
        <color rgba="0.152941 0.152941 0.152941 1"/>
      </material>
    </visual>
    <collision>
      <origin xyz="2.77556e-17 -6.93889e-18 0.01625" rpy="1.5708 5.55112e-17 0"/>
      <geometry>
        <mesh filename="package://meshes/wheel4_omniwheel_tyre_v1.stl"/>
      </geometry>
    </collision>
  </link>
  <!-- Joint from wheel4_shaft_holder_v2 to wheel4_omniwheel_tyre_v1_16 -->
  <joint name="wheel_3e" type="continuous">
    <origin xyz="-0.0384102 -0.0124802 0.0065" rpy="-1.5708 -0.971379 -2.82743"/>
    <parent link="wheel4_shaft_holder_v2"/>
    <child link="wheel4_omniwheel_tyre_v1_16"/>
    <axis xyz="0 0 1"/>
    <limit effort="5" velocity="10"/>
    <joint_properties friction="0.1"/>
  </joint>
  <!-- Link wheel4_omniwheel_tyre_v1_17 -->
  <link name="wheel4_omniwheel_tyre_v1_17">
    <inertial>
      <origin xyz="-6.93633e-10 9.25426e-19 1.35567e-09" rpy="0 0 0"/>
      <mass value="0.00502735"/>
      <inertia ixx="2.29535e-07" ixy="-3.18544e-24" ixz="8.11134e-13" iyy="2.29535e-07" iyz="-6.37088e-24" izz="2.32706e-07"/>
    </inertial>
    <!-- Part wheel4_omniwheel_tyre_v1_17 -->
    <visual>
      <origin xyz="1.38778e-17 0 0.01625" rpy="1.5708 -0 -1.38778e-17"/>
      <geometry>
        <mesh filename="package://meshes/wheel4_omniwheel_tyre_v1.stl"/>
      </geometry>
      <material name="wheel4_omniwheel_tyre_v1_17_material">
        <color rgba="0.152941 0.152941 0.152941 1"/>
      </material>
    </visual>
    <collision>
      <origin xyz="1.38778e-17 0 0.01625" rpy="1.5708 -0 -1.38778e-17"/>
      <geometry>
        <mesh filename="package://meshes/wheel4_omniwheel_tyre_v1.stl"/>
      </geometry>
    </collision>
  </link>
  <!-- Joint from wheel4_shaft_holder_v2 to wheel4_omniwheel_tyre_v1_17 -->
  <joint name="wheel_3d" type="continuous">
    <origin xyz="-0.0237388 -0.0326737 0.0065" rpy="-1.5708 -0.240455 -2.19911"/>
    <parent link="wheel4_shaft_holder_v2"/>
    <child link="wheel4_omniwheel_tyre_v1_17"/>
    <axis xyz="0 0 1"/>
    <limit effort="5" velocity="10"/>
    <joint_properties friction="0.1"/>
  </joint>
  <!-- Link wheel4_omniwheel_tyre_v1_18 -->
  <link name="wheel4_omniwheel_tyre_v1_18">
    <inertial>
      <origin xyz="-6.93633e-10 1.44771e-17 1.35567e-09" rpy="0 0 0"/>
      <mass value="0.00502735"/>
      <inertia ixx="2.29535e-07" ixy="1.62789e-29" ixz="8.11134e-13" iyy="2.29535e-07" iyz="6.3632e-26" izz="2.32706e-07"/>
    </inertial>
    <!-- Part wheel4_omniwheel_tyre_v1_18 -->
    <visual>
      <origin xyz="0 1.38778e-17 0.01625" rpy="1.5708 5.20093e-17 5.38162e-33"/>
      <geometry>
        <mesh filename="package://meshes/wheel4_omniwheel_tyre_v1.stl"/>
      </geometry>
      <material name="wheel4_omniwheel_tyre_v1_18_material">
        <color rgba="0.152941 0.152941 0.152941 1"/>
      </material>
    </visual>
    <collision>
      <origin xyz="0 1.38778e-17 0.01625" rpy="1.5708 5.20093e-17 5.38162e-33"/>
      <geometry>
        <mesh filename="package://meshes/wheel4_omniwheel_tyre_v1.stl"/>
      </geometry>
    </collision>
  </link>
  <!-- Joint from wheel4_shaft_holder_v2 to wheel4_omniwheel_tyre_v1_18 -->
  <joint name="wheel_3c" type="continuous">
    <origin xyz="-3.46945e-18 -0.0403869 0.0065" rpy="-1.5708 -6.10623e-16 -1.5708"/>
    <parent link="wheel4_shaft_holder_v2"/>
    <child link="wheel4_omniwheel_tyre_v1_18"/>
    <axis xyz="0 0 1"/>
    <limit effort="5" velocity="10"/>
    <joint_properties friction="0.1"/>
  </joint>
  <!-- Link wheel4_omniwheel_tyre_v1_19 -->
  <link name="wheel4_omniwheel_tyre_v1_19">
    <inertial>
      <origin xyz="-6.93633e-10 1.48032e-17 1.35567e-09" rpy="0 0 0"/>
      <mass value="0.00502735"/>
      <inertia ixx="2.29535e-07" ixy="6.37087e-24" ixz="8.11134e-13" iyy="2.29535e-07" iyz="-3.18541e-24" izz="2.32706e-07"/>
    </inertial>
    <!-- Part wheel4_omniwheel_tyre_v1_19 -->
    <visual>
      <origin xyz="0 1.38778e-17 0.01625" rpy="1.5708 1.11022e-16 2.77556e-17"/>
      <geometry>
        <mesh filename="package://meshes/wheel4_omniwheel_tyre_v1.stl"/>
      </geometry>
      <material name="wheel4_omniwheel_tyre_v1_19_material">
        <color rgba="0.152941 0.152941 0.152941 1"/>
      </material>
    </visual>
    <collision>
      <origin xyz="0 1.38778e-17 0.01625" rpy="1.5708 1.11022e-16 2.77556e-17"/>
      <geometry>
        <mesh filename="package://meshes/wheel4_omniwheel_tyre_v1.stl"/>
      </geometry>
    </collision>
  </link>
  <!-- Joint from wheel4_shaft_holder_v2 to wheel4_omniwheel_tyre_v1_19 -->
  <joint name="wheel_3b" type="continuous">
    <origin xyz="0.0237388 -0.0326737 0.0065" rpy="-1.5708 -0.210366 -0.942478"/>
    <parent link="wheel4_shaft_holder_v2"/>
    <child link="wheel4_omniwheel_tyre_v1_19"/>
    <axis xyz="0 0 1"/>
    <limit effort="5" velocity="10"/>
    <joint_properties friction="0.1"/>
  </joint>
  <!-- Link wheel4_omniwheel_tyre_v1_20 -->
  <link name="wheel4_omniwheel_tyre_v1_20">
    <inertial>
      <origin xyz="5.72708e-10 3.91321e-10 1.35567e-09" rpy="0 0 0"/>
      <mass value="0.00502735"/>
      <inertia ixx="2.29535e-07" ixy="1.05879e-21" ixz="-6.69724e-13" iyy="2.29535e-07" iyz="-4.5761e-13" izz="2.32706e-07"/>
    </inertial>
    <!-- Part wheel4_omniwheel_tyre_v1_20 -->
    <visual>
      <origin xyz="-1.38778e-17 0 0.01625" rpy="1.5708 1.38778e-16 -2.54218"/>
      <geometry>
        <mesh filename="package://meshes/wheel4_omniwheel_tyre_v1.stl"/>
      </geometry>
      <material name="wheel4_omniwheel_tyre_v1_20_material">
        <color rgba="0.152941 0.152941 0.152941 1"/>
      </material>
    </visual>
    <collision>
      <origin xyz="-1.38778e-17 0 0.01625" rpy="1.5708 1.38778e-16 -2.54218"/>
      <geometry>
        <mesh filename="package://meshes/wheel4_omniwheel_tyre_v1.stl"/>
      </geometry>
    </collision>
  </link>
  <!-- Joint from wheel4_shaft_holder_v2 to wheel4_omniwheel_tyre_v1_20 -->
  <joint name="wheel_3a" type="continuous">
    <origin xyz="0.0384102 -0.0124802 0.0065" rpy="-1.25664 1.5708 0"/>
    <parent link="wheel4_shaft_holder_v2"/>
    <child link="wheel4_omniwheel_tyre_v1_20"/>
    <axis xyz="0 0 1"/>
    <limit effort="5" velocity="10"/>
    <joint_properties friction="0.1"/>
  </joint>
  <!-- Joint from part_1 to wheel4_shaft_holder_v2 -->
  <joint name="wheel_motorC" type="continuous">
    <origin xyz="4.91505e-18 -0.105 0.0125" rpy="1.5708 -1.5708 0"/>
    <parent link="part_1"/>
    <child link="wheel4_shaft_holder_v2"/>
    <axis xyz="0 0 1"/>
    <limit effort="5" velocity="10"/>
    <joint_properties friction="0.1"/>
  </joint>
  <!-- Link wheel4_shaft_holder_v2_2 -->
  <link name="wheel4_shaft_holder_v2_2">
    <inertial>
      <origin xyz="3.57042e-13 3.57038e-13 0.0159932" rpy="0 0 0"/>
      <mass value="0.162524"/>
      <inertia ixx="0.000106018" ixy="-1.52466e-20" ixz="-4.58451e-15" iyy="0.000106018" iyz="-5.68703e-15" izz="0.000180425"/>
    </inertial>
    <!-- Part wheel4_shaft_omni_v1_21 -->
    <!-- Part wheel4_shaft_omni_v1_22 -->
    <!-- Part wheel4_shaft_omni_v1_23 -->
    <!-- Part wheel4_shaft_omni_v1_24 -->
    <!-- Part wheel4_shaft_omni_v1_25 -->
    <!-- Part wheel4_shaft_omni_v1_26 -->
    <!-- Part wheel4_shaft_omni_v1_27 -->
    <!-- Part wheel4_shaft_omni_v1_28 -->
    <!-- Part wheel4_shaft_holder_v2_2 -->
    <visual>
      <origin xyz="-1.73472e-18 -2.02384e-17 0.013" rpy="1.5708 -1.5708 0"/>
      <geometry>
        <mesh filename="package://meshes/wheel4_shaft_holder_v2.stl"/>
      </geometry>
      <material name="wheel4_shaft_holder_v2_2_material">
        <color rgba="0.627451 0.627451 0.627451 1"/>
      </material>
    </visual>
    <!-- Part wheel4_body_omni_v4_3 -->
    <visual>
      <origin xyz="0 0 0.013" rpy="1.5708 1.5708 0"/>
      <geometry>
        <mesh filename="package://meshes/wheel4_body_omni_v4__2.stl"/>
      </geometry>
      <material name="wheel4_body_omni_v4_3_material">
        <color rgba="0.627451 0.627451 0.627451 1"/>
      </material>
    </visual>
    <!-- Part wheel4_shaft_omni_v1_29 -->
    <!-- Part wheel4_shaft_omni_v1_30 -->
    <!-- Part wheel4_shaft_omni_v1_31 -->
    <!-- Part wheel4_shaft_omni_v1_32 -->
    <!-- Part wheel4_shaft_omni_v1_33 -->
    <!-- Part wheel4_shaft_omni_v1_34 -->
    <!-- Part wheel4_shaft_omni_v1_35 -->
    <!-- Part wheel4_body_omni_v4_4 -->
    <visual>
      <origin xyz="-2.25514e-17 -2.02384e-17 0.032" rpy="-3.38788e-16 1.5708 0"/>
      <geometry>
        <mesh filename="package://meshes/wheel4_body_omni_v4.stl"/>
      </geometry>
      <material name="wheel4_body_omni_v4_4_material">
        <color rgba="0.627451 0.627451 0.627451 1"/>
      </material>
    </visual>
    <!-- Part wheel4_shaft_omni_v1_36 -->
    <!-- Part wheel4_shaft_omni_v1_37 -->
    <!-- Part wheel4_shaft_omni_v1_38 -->
    <!-- Part wheel4_shaft_omni_v1_39 -->
    <!-- Part wheel4_shaft_omni_v1_40 -->
  </link>
  <!-- Frame motorA (dummy link + fixed joint) -->
  <link name="motorA">
    <origin xyz="0 0 0" rpy="0 -0 0"/>
    <inertial>
      <origin xyz="0 0 0" rpy="0 0 0"/>
      <mass value="1e-9"/>
      <inertia ixx="0" ixy="0" ixz="0" iyy="0" iyz="0" izz="0"/>
    </inertial>
  </link>
  <joint name="motorA_frame" type="fixed">
    <origin xyz="0 3.37024e-19 0" rpy="3.14159 -1.12014e-59 -1.5708"/>
    <parent link="wheel4_shaft_holder_v2_2"/>
    <child link="motorA"/>
    <axis xyz="0 0 0"/>
  </joint>
  <!-- Link wheel4_omniwheel_tyre_v1_21 -->
  <link name="wheel4_omniwheel_tyre_v1_21">
    <inertial>
      <origin xyz="-6.93633e-10 1.44771e-17 1.35567e-09" rpy="0 0 0"/>
      <mass value="0.00502735"/>
      <inertia ixx="2.29535e-07" ixy="-1.27417e-23" ixz="8.11134e-13" iyy="2.29535e-07" iyz="6.3632e-26" izz="2.32706e-07"/>
    </inertial>
    <!-- Part wheel4_omniwheel_tyre_v1_21 -->
    <visual>
      <origin xyz="1.38778e-17 1.38778e-17 0.01625" rpy="1.5708 5.20093e-17 0"/>
      <geometry>
        <mesh filename="package://meshes/wheel4_omniwheel_tyre_v1.stl"/>
      </geometry>
      <material name="wheel4_omniwheel_tyre_v1_21_material">
        <color rgba="0.152941 0.152941 0.152941 1"/>
      </material>
    </visual>
    <collision>
      <origin xyz="1.38778e-17 1.38778e-17 0.01625" rpy="1.5708 5.20093e-17 0"/>
      <geometry>
        <mesh filename="package://meshes/wheel4_omniwheel_tyre_v1.stl"/>
      </geometry>
    </collision>
  </link>
  <!-- Joint from wheel4_shaft_holder_v2_2 to wheel4_omniwheel_tyre_v1_21 -->
  <joint name="wheel_k" type="continuous">
    <origin xyz="-0.0403869 -6.36065e-18 0.0255" rpy="1.5708 0.992087 -3.14159"/>
    <parent link="wheel4_shaft_holder_v2_2"/>
    <child link="wheel4_omniwheel_tyre_v1_21"/>
    <axis xyz="0 0 1"/>
    <limit effort="5" velocity="10"/>
    <joint_properties friction="0.1"/>
  </joint>
  <!-- Link wheel4_omniwheel_tyre_v1_22 -->
  <link name="wheel4_omniwheel_tyre_v1_22">
    <inertial>
      <origin xyz="-6.93633e-10 -1.47565e-17 1.35567e-09" rpy="0 0 0"/>
      <mass value="0.00502735"/>
      <inertia ixx="2.29535e-07" ixy="-3.82252e-23" ixz="8.11134e-13" iyy="2.29535e-07" iyz="1.94646e-23" izz="2.32706e-07"/>
    </inertial>
    <!-- Part wheel4_omniwheel_tyre_v1_22 -->
    <visual>
      <origin xyz="-1.38778e-17 -1.38778e-17 0.01625" rpy="1.5708 -5.55112e-17 -5.55112e-17"/>
      <geometry>
        <mesh filename="package://meshes/wheel4_omniwheel_tyre_v1.stl"/>
      </geometry>
      <material name="wheel4_omniwheel_tyre_v1_22_material">
        <color rgba="0.152941 0.152941 0.152941 1"/>
      </material>
    </visual>
    <collision>
      <origin xyz="-1.38778e-17 -1.38778e-17 0.01625" rpy="1.5708 -5.55112e-17 -5.55112e-17"/>
      <geometry>
        <mesh filename="package://meshes/wheel4_omniwheel_tyre_v1.stl"/>
      </geometry>
    </collision>
  </link>
  <!-- Joint from wheel4_shaft_holder_v2_2 to wheel4_omniwheel_tyre_v1_22 -->
  <joint name="wheel_l" type="continuous">
    <origin xyz="-0.0326737 0.0237388 0.0255" rpy="1.5708 -0.508017 2.51327"/>
    <parent link="wheel4_shaft_holder_v2_2"/>
    <child link="wheel4_omniwheel_tyre_v1_22"/>
    <axis xyz="0 0 1"/>
    <limit effort="5" velocity="10"/>
    <joint_properties friction="0.1"/>
  </joint>
  <!-- Link wheel4_omniwheel_tyre_v1_23 -->
  <link name="wheel4_omniwheel_tyre_v1_23">
    <inertial>
      <origin xyz="-6.93633e-10 5.87155e-19 1.35567e-09" rpy="0 0 0"/>
      <mass value="0.00502735"/>
      <inertia ixx="2.29535e-07" ixy="-2.38906e-24" ixz="8.11134e-13" iyy="2.29535e-07" iyz="-3.32186e-25" izz="2.32706e-07"/>
    </inertial>
    <!-- Part wheel4_omniwheel_tyre_v1_23 -->
    <visual>
      <origin xyz="0 0 0.01625" rpy="1.5708 5.55112e-17 -9.54098e-18"/>
      <geometry>
        <mesh filename="package://meshes/wheel4_omniwheel_tyre_v1.stl"/>
      </geometry>
      <material name="wheel4_omniwheel_tyre_v1_23_material">
        <color rgba="0.152941 0.152941 0.152941 1"/>
      </material>
    </visual>
    <collision>
      <origin xyz="0 0 0.01625" rpy="1.5708 5.55112e-17 -9.54098e-18"/>
      <geometry>
        <mesh filename="package://meshes/wheel4_omniwheel_tyre_v1.stl"/>
      </geometry>
    </collision>
  </link>
  <!-- Joint from wheel4_shaft_holder_v2_2 to wheel4_omniwheel_tyre_v1_23 -->
  <joint name="wheel_m" type="continuous">
    <origin xyz="-0.0124802 0.0384102 0.0255" rpy="1.5708 -0.0501607 1.88496"/>
    <parent link="wheel4_shaft_holder_v2_2"/>
    <child link="wheel4_omniwheel_tyre_v1_23"/>
    <axis xyz="0 0 1"/>
    <limit effort="5" velocity="10"/>
    <joint_properties friction="0.1"/>
  </joint>
  <!-- Link wheel4_omniwheel_tyre_v1_24 -->
  <link name="wheel4_omniwheel_tyre_v1_24">
    <inertial>
      <origin xyz="-6.93633e-10 6.43533e-19 1.35567e-09" rpy="0 0 0"/>
      <mass value="0.00502735"/>
      <inertia ixx="2.29535e-07" ixy="-4.57905e-24" ixz="8.11134e-13" iyy="2.29535e-07" iyz="-3.43184e-25" izz="2.32706e-07"/>
    </inertial>
    <!-- Part wheel4_omniwheel_tyre_v1_24 -->
    <visual>
      <origin xyz="-6.93889e-18 0 0.01625" rpy="1.5708 1.11022e-16 -7.80626e-18"/>
      <geometry>
        <mesh filename="package://meshes/wheel4_omniwheel_tyre_v1.stl"/>
      </geometry>
      <material name="wheel4_omniwheel_tyre_v1_24_material">
        <color rgba="0.152941 0.152941 0.152941 1"/>
      </material>
    </visual>
    <collision>
      <origin xyz="-6.93889e-18 0 0.01625" rpy="1.5708 1.11022e-16 -7.80626e-18"/>
      <geometry>
        <mesh filename="package://meshes/wheel4_omniwheel_tyre_v1.stl"/>
      </geometry>
    </collision>
  </link>
  <!-- Joint from wheel4_shaft_holder_v2_2 to wheel4_omniwheel_tyre_v1_24 -->
  <joint name="wheel_n" type="continuous">
    <origin xyz="0.0124802 0.0384102 0.0255" rpy="-1.5708 -0.0501607 1.25664"/>
    <parent link="wheel4_shaft_holder_v2_2"/>
    <child link="wheel4_omniwheel_tyre_v1_24"/>
    <axis xyz="0 0 1"/>
    <limit effort="5" velocity="10"/>
    <joint_properties friction="0.1"/>
  </joint>
  <!-- Link wheel4_omniwheel_tyre_v1_25 -->
  <link name="wheel4_omniwheel_tyre_v1_25">
    <inertial>
      <origin xyz="-6.93633e-10 4.74398e-19 1.35567e-09" rpy="0 0 0"/>
      <mass value="0.00502735"/>
      <inertia ixx="2.29535e-07" ixy="2.54835e-23" ixz="8.11134e-13" iyy="2.29535e-07" iyz="8.80474e-26" izz="2.32706e-07"/>
    </inertial>
    <!-- Part wheel4_omniwheel_tyre_v1_25 -->
    <visual>
      <origin xyz="-1.38778e-17 0 0.01625" rpy="1.5708 5.55112e-17 5.55112e-17"/>
      <geometry>
        <mesh filename="package://meshes/wheel4_omniwheel_tyre_v1.stl"/>
      </geometry>
      <material name="wheel4_omniwheel_tyre_v1_25_material">
        <color rgba="0.152941 0.152941 0.152941 1"/>
      </material>
    </visual>
    <collision>
      <origin xyz="-1.38778e-17 0 0.01625" rpy="1.5708 5.55112e-17 5.55112e-17"/>
      <geometry>
        <mesh filename="package://meshes/wheel4_omniwheel_tyre_v1.stl"/>
      </geometry>
    </collision>
  </link>
  <!-- Joint from wheel4_shaft_holder_v2_2 to wheel4_omniwheel_tyre_v1_25 -->
  <joint name="wheel_o" type="continuous">
    <origin xyz="0.0326737 0.0237388 0.0255" rpy="-1.5708 -0.508017 0.628319"/>
    <parent link="wheel4_shaft_holder_v2_2"/>
    <child link="wheel4_omniwheel_tyre_v1_25"/>
    <axis xyz="0 0 1"/>
    <limit effort="5" velocity="10"/>
    <joint_properties friction="0.1"/>
  </joint>
  <!-- Link wheel4_omniwheel_tyre_v1_26 -->
  <link name="wheel4_omniwheel_tyre_v1_26">
    <inertial>
      <origin xyz="-6.93633e-10 7.53819e-18 1.35567e-09" rpy="0 0 0"/>
      <mass value="0.00502735"/>
      <inertia ixx="2.29535e-07" ixy="-1.27417e-23" ixz="8.11134e-13" iyy="2.29535e-07" iyz="6.3632e-26" izz="2.32706e-07"/>
    </inertial>
    <!-- Part wheel4_omniwheel_tyre_v1_26 -->
    <visual>
      <origin xyz="0 6.93889e-18 0.01625" rpy="1.5708 5.20093e-17 0"/>
      <geometry>
        <mesh filename="package://meshes/wheel4_omniwheel_tyre_v1.stl"/>
      </geometry>
      <material name="wheel4_omniwheel_tyre_v1_26_material">
        <color rgba="0.152941 0.152941 0.152941 1"/>
      </material>
    </visual>
    <collision>
      <origin xyz="0 6.93889e-18 0.01625" rpy="1.5708 5.20093e-17 0"/>
      <geometry>
        <mesh filename="package://meshes/wheel4_omniwheel_tyre_v1.stl"/>
      </geometry>
    </collision>
  </link>
  <!-- Joint from wheel4_shaft_holder_v2_2 to wheel4_omniwheel_tyre_v1_26 -->
  <joint name="wheel_p" type="continuous">
    <origin xyz="0.0403869 -6.36065e-18 0.0255" rpy="1.5708 0.992087 -3.14159"/>
    <parent link="wheel4_shaft_holder_v2_2"/>
    <child link="wheel4_omniwheel_tyre_v1_26"/>
    <axis xyz="0 0 1"/>
    <limit effort="5" velocity="10"/>
    <joint_properties friction="0.1"/>
  </joint>
  <!-- Link wheel4_omniwheel_tyre_v1_27 -->
  <link name="wheel4_omniwheel_tyre_v1_27">
    <inertial>
      <origin xyz="-6.93633e-10 -4.27659e-19 1.35567e-09" rpy="0 0 0"/>
      <mass value="0.00502735"/>
      <inertia ixx="2.29535e-07" ixy="-2.54834e-23" ixz="8.11134e-13" iyy="2.29535e-07" iyz="1.93766e-23" izz="2.32706e-07"/>
    </inertial>
    <!-- Part wheel4_omniwheel_tyre_v1_27 -->
    <visual>
      <origin xyz="-1.04083e-17 0 0.01625" rpy="1.5708 5.55112e-17 0"/>
      <geometry>
        <mesh filename="package://meshes/wheel4_omniwheel_tyre_v1.stl"/>
      </geometry>
      <material name="wheel4_omniwheel_tyre_v1_27_material">
        <color rgba="0.152941 0.152941 0.152941 1"/>
      </material>
    </visual>
    <collision>
      <origin xyz="-1.04083e-17 0 0.01625" rpy="1.5708 5.55112e-17 0"/>
      <geometry>
        <mesh filename="package://meshes/wheel4_omniwheel_tyre_v1.stl"/>
      </geometry>
    </collision>
  </link>
  <!-- Joint from wheel4_shaft_holder_v2_2 to wheel4_omniwheel_tyre_v1_27 -->
  <joint name="wheel_q" type="continuous">
    <origin xyz="0.0326737 -0.0237388 0.0255" rpy="1.5708 -0.508017 2.51327"/>
    <parent link="wheel4_shaft_holder_v2_2"/>
    <child link="wheel4_omniwheel_tyre_v1_27"/>
    <axis xyz="0 0 1"/>
    <limit effort="5" velocity="10"/>
    <joint_properties friction="0.1"/>
  </joint>
  <!-- Link wheel4_omniwheel_tyre_v1_28 -->
  <link name="wheel4_omniwheel_tyre_v1_28">
    <inertial>
      <origin xyz="-6.93633e-10 1.43522e-17 1.35567e-09" rpy="0 0 0"/>
      <mass value="0.00502735"/>
      <inertia ixx="2.29535e-07" ixy="-3.02616e-23" ixz="8.11134e-13" iyy="2.29535e-07" iyz="8.79573e-26" izz="2.32706e-07"/>
    </inertial>
    <!-- Part wheel4_omniwheel_tyre_v1_28 -->
    <visual>
      <origin xyz="-1.38778e-17 1.38778e-17 0.01625" rpy="1.5708 1.11022e-16 -5.55112e-17"/>
      <geometry>
        <mesh filename="package://meshes/wheel4_omniwheel_tyre_v1.stl"/>
      </geometry>
      <material name="wheel4_omniwheel_tyre_v1_28_material">
        <color rgba="0.152941 0.152941 0.152941 1"/>
      </material>
    </visual>
    <collision>
      <origin xyz="-1.38778e-17 1.38778e-17 0.01625" rpy="1.5708 1.11022e-16 -5.55112e-17"/>
      <geometry>
        <mesh filename="package://meshes/wheel4_omniwheel_tyre_v1.stl"/>
      </geometry>
    </collision>
  </link>
  <!-- Joint from wheel4_shaft_holder_v2_2 to wheel4_omniwheel_tyre_v1_28 -->
  <joint name="wheel_r" type="continuous">
    <origin xyz="0.0124802 -0.0384102 0.0255" rpy="1.5708 0.514194 1.88496"/>
    <parent link="wheel4_shaft_holder_v2_2"/>
    <child link="wheel4_omniwheel_tyre_v1_28"/>
    <axis xyz="0 0 1"/>
    <limit effort="5" velocity="10"/>
    <joint_properties friction="0.1"/>
  </joint>
  <!-- Link wheel4_omniwheel_tyre_v1_29 -->
  <link name="wheel4_omniwheel_tyre_v1_29">
    <inertial>
      <origin xyz="-6.93633e-10 2.83709e-17 1.35567e-09" rpy="0 0 0"/>
      <mass value="0.00502735"/>
      <inertia ixx="2.29535e-07" ixy="-1.19452e-24" ixz="8.11134e-13" iyy="2.29535e-07" iyz="-3.37674e-25" izz="2.32706e-07"/>
    </inertial>
    <!-- Part wheel4_omniwheel_tyre_v1_29 -->
    <visual>
      <origin xyz="6.93889e-18 2.77556e-17 0.01625" rpy="1.5708 5.55112e-17 5.20417e-18"/>
      <geometry>
        <mesh filename="package://meshes/wheel4_omniwheel_tyre_v1.stl"/>
      </geometry>
      <material name="wheel4_omniwheel_tyre_v1_29_material">
        <color rgba="0.152941 0.152941 0.152941 1"/>
      </material>
    </visual>
    <collision>
      <origin xyz="6.93889e-18 2.77556e-17 0.01625" rpy="1.5708 5.55112e-17 5.20417e-18"/>
      <geometry>
        <mesh filename="package://meshes/wheel4_omniwheel_tyre_v1.stl"/>
      </geometry>
    </collision>
  </link>
  <!-- Joint from wheel4_shaft_holder_v2_2 to wheel4_omniwheel_tyre_v1_29 -->
  <joint name="wheel_s" type="continuous">
    <origin xyz="-0.0124802 -0.0384102 0.0255" rpy="-1.5708 -0.0501607 1.25664"/>
    <parent link="wheel4_shaft_holder_v2_2"/>
    <child link="wheel4_omniwheel_tyre_v1_29"/>
    <axis xyz="0 0 1"/>
    <limit effort="5" velocity="10"/>
    <joint_properties friction="0.1"/>
  </joint>
  <!-- Link wheel4_omniwheel_tyre_v1_30 -->
  <link name="wheel4_omniwheel_tyre_v1_30">
    <inertial>
      <origin xyz="-6.93633e-10 -2.63791e-17 1.35567e-09" rpy="0 0 0"/>
      <mass value="0.00502735"/>
      <inertia ixx="2.29535e-07" ixy="1.27417e-23" ixz="8.11134e-13" iyy="2.29535e-07" iyz="-6.45888e-24" izz="2.32706e-07"/>
    </inertial>
    <!-- Part wheel4_omniwheel_tyre_v1_30 -->
    <visual>
      <origin xyz="1.38778e-17 -2.77556e-17 0.01625" rpy="1.5708 5.55112e-17 0"/>
      <geometry>
        <mesh filename="package://meshes/wheel4_omniwheel_tyre_v1.stl"/>
      </geometry>
      <material name="wheel4_omniwheel_tyre_v1_30_material">
        <color rgba="0.152941 0.152941 0.152941 1"/>
      </material>
    </visual>
    <collision>
      <origin xyz="1.38778e-17 -2.77556e-17 0.01625" rpy="1.5708 5.55112e-17 0"/>
      <geometry>
        <mesh filename="package://meshes/wheel4_omniwheel_tyre_v1.stl"/>
      </geometry>
    </collision>
  </link>
  <!-- Joint from wheel4_shaft_holder_v2_2 to wheel4_omniwheel_tyre_v1_30 -->
  <joint name="wheel_t" type="continuous">
    <origin xyz="-0.0326737 -0.0237388 0.0255" rpy="-1.5708 -0.508017 0.628319"/>
    <parent link="wheel4_shaft_holder_v2_2"/>
    <child link="wheel4_omniwheel_tyre_v1_30"/>
    <axis xyz="0 0 1"/>
    <limit effort="5" velocity="10"/>
    <joint_properties friction="0.1"/>
  </joint>
  <!-- Link wheel4_omniwheel_tyre_v1_31 -->
  <link name="wheel4_omniwheel_tyre_v1_31">
    <inertial>
      <origin xyz="-6.93633e-10 5.56244e-18 -1.46309e-09" rpy="0 0 0"/>
      <mass value="0.00502735"/>
      <inertia ixx="2.29535e-07" ixy="1.27418e-23" ixz="-8.11134e-13" iyy="2.29535e-07" iyz="-6.45888e-24" izz="2.32706e-07"/>
    </inertial>
    <!-- Part wheel4_omniwheel_tyre_v1_31 -->
    <visual>
      <origin xyz="2.77556e-17 6.93889e-18 -0.01625" rpy="-1.5708 -2.77556e-17 0"/>
      <geometry>
        <mesh filename="package://meshes/wheel4_omniwheel_tyre_v1.stl"/>
      </geometry>
      <material name="wheel4_omniwheel_tyre_v1_31_material">
        <color rgba="0.152941 0.152941 0.152941 1"/>
      </material>
    </visual>
    <collision>
      <origin xyz="2.77556e-17 6.93889e-18 -0.01625" rpy="-1.5708 -2.77556e-17 0"/>
      <geometry>
        <mesh filename="package://meshes/wheel4_omniwheel_tyre_v1.stl"/>
      </geometry>
    </collision>
  </link>
  <!-- Joint from wheel4_shaft_holder_v2_2 to wheel4_omniwheel_tyre_v1_31 -->
  <joint name="wheel_j" type="continuous">
    <origin xyz="0.0384102 0.0124802 0.0065" rpy="-1.5708 -0.971379 0.314159"/>
    <parent link="wheel4_shaft_holder_v2_2"/>
    <child link="wheel4_omniwheel_tyre_v1_31"/>
    <axis xyz="0 0 1"/>
    <limit effort="5" velocity="10"/>
    <joint_properties friction="0.1"/>
  </joint>
  <!-- Link wheel4_omniwheel_tyre_v1_32 -->
  <link name="wheel4_omniwheel_tyre_v1_32">
    <inertial>
      <origin xyz="-6.93633e-10 2.48884e-19 1.35567e-09" rpy="0 0 0"/>
      <mass value="0.00502735"/>
      <inertia ixx="2.29535e-07" ixy="-6.37084e-24" ixz="8.11134e-13" iyy="2.29535e-07" iyz="6.50289e-24" izz="2.32706e-07"/>
    </inertial>
    <!-- Part wheel4_omniwheel_tyre_v1_32 -->
    <visual>
      <origin xyz="0 0 0.01625" rpy="1.5708 -5.55112e-17 1.38778e-17"/>
      <geometry>
        <mesh filename="package://meshes/wheel4_omniwheel_tyre_v1.stl"/>
      </geometry>
      <material name="wheel4_omniwheel_tyre_v1_32_material">
        <color rgba="0.152941 0.152941 0.152941 1"/>
      </material>
    </visual>
    <collision>
      <origin xyz="0 0 0.01625" rpy="1.5708 -5.55112e-17 1.38778e-17"/>
      <geometry>
        <mesh filename="package://meshes/wheel4_omniwheel_tyre_v1.stl"/>
      </geometry>
    </collision>
  </link>
  <!-- Joint from wheel4_shaft_holder_v2_2 to wheel4_omniwheel_tyre_v1_32 -->
  <joint name="wheel_i" type="continuous">
    <origin xyz="0.0237388 0.0326737 0.0065" rpy="1.5708 -0.210366 0.942478"/>
    <parent link="wheel4_shaft_holder_v2_2"/>
    <child link="wheel4_omniwheel_tyre_v1_32"/>
    <axis xyz="0 0 1"/>
    <limit effort="5" velocity="10"/>
    <joint_properties friction="0.1"/>
  </joint>
  <!-- Link wheel4_omniwheel_tyre_v1_33 -->
  <link name="wheel4_omniwheel_tyre_v1_33">
    <inertial>
      <origin xyz="-1.15103e-17 -6.93633e-10 1.35567e-09" rpy="0 0 0"/>
      <mass value="0.00502735"/>
      <inertia ixx="2.29535e-07" ixy="1.22108e-27" ixz="4.77352e-24" iyy="2.29535e-07" iyz="8.11134e-13" izz="2.32706e-07"/>
    </inertial>
    <!-- Part wheel4_omniwheel_tyre_v1_33 -->
    <visual>
      <origin xyz="1.38778e-17 2.77556e-17 0.01625" rpy="1.5708 6.89294e-16 1.5708"/>
      <geometry>
        <mesh filename="package://meshes/wheel4_omniwheel_tyre_v1.stl"/>
      </geometry>
      <material name="wheel4_omniwheel_tyre_v1_33_material">
        <color rgba="0.152941 0.152941 0.152941 1"/>
      </material>
    </visual>
    <collision>
      <origin xyz="1.38778e-17 2.77556e-17 0.01625" rpy="1.5708 6.89294e-16 1.5708"/>
      <geometry>
        <mesh filename="package://meshes/wheel4_omniwheel_tyre_v1.stl"/>
      </geometry>
    </collision>
  </link>
  <!-- Joint from wheel4_shaft_holder_v2_2 to wheel4_omniwheel_tyre_v1_33 -->
  <joint name="wheel_h" type="continuous">
    <origin xyz="-1.73472e-18 0.0403869 0.0065" rpy="-4.44089e-16 1.5708 0"/>
    <parent link="wheel4_shaft_holder_v2_2"/>
    <child link="wheel4_omniwheel_tyre_v1_33"/>
    <axis xyz="0 0 1"/>
    <limit effort="5" velocity="10"/>
    <joint_properties friction="0.1"/>
  </joint>
  <!-- Link wheel4_omniwheel_tyre_v1_34 -->
  <link name="wheel4_omniwheel_tyre_v1_34">
    <inertial>
      <origin xyz="-6.93633e-10 -1.34034e-17 1.35567e-09" rpy="0 0 0"/>
      <mass value="0.00502735"/>
      <inertia ixx="2.29535e-07" ixy="6.3709e-24" ixz="8.11134e-13" iyy="2.29535e-07" iyz="6.45888e-24" izz="2.32706e-07"/>
    </inertial>
    <!-- Part wheel4_omniwheel_tyre_v1_34 -->
    <visual>
      <origin xyz="6.93889e-18 -1.38778e-17 0.01625" rpy="1.5708 5.55112e-17 0"/>
      <geometry>
        <mesh filename="package://meshes/wheel4_omniwheel_tyre_v1.stl"/>
      </geometry>
      <material name="wheel4_omniwheel_tyre_v1_34_material">
        <color rgba="0.152941 0.152941 0.152941 1"/>
      </material>
    </visual>
    <collision>
      <origin xyz="6.93889e-18 -1.38778e-17 0.01625" rpy="1.5708 5.55112e-17 0"/>
      <geometry>
        <mesh filename="package://meshes/wheel4_omniwheel_tyre_v1.stl"/>
      </geometry>
    </collision>
  </link>
  <!-- Joint from wheel4_shaft_holder_v2_2 to wheel4_omniwheel_tyre_v1_34 -->
  <joint name="wheel_g" type="continuous">
    <origin xyz="-0.0237388 0.0326737 0.0065" rpy="1.5708 -0.210366 2.19911"/>
    <parent link="wheel4_shaft_holder_v2_2"/>
    <child link="wheel4_omniwheel_tyre_v1_34"/>
    <axis xyz="0 0 1"/>
    <limit effort="5" velocity="10"/>
    <joint_properties friction="0.1"/>
  </joint>
  <!-- Link wheel4_omniwheel_tyre_v1_35 -->
  <link name="wheel4_omniwheel_tyre_v1_35">
    <inertial>
      <origin xyz="-6.93633e-10 -6.01347e-18 1.35567e-09" rpy="0 0 0"/>
      <mass value="0.00502735"/>
      <inertia ixx="2.29535e-07" ixy="1.27417e-23" ixz="8.11134e-13" iyy="2.29535e-07" iyz="-1.27418e-23" izz="2.32706e-07"/>
    </inertial>
    <!-- Part wheel4_omniwheel_tyre_v1_35 -->
    <visual>
      <origin xyz="0 -6.93889e-18 0.01625" rpy="1.5708 2.77556e-17 -5.55112e-17"/>
      <geometry>
        <mesh filename="package://meshes/wheel4_omniwheel_tyre_v1.stl"/>
      </geometry>
      <material name="wheel4_omniwheel_tyre_v1_35_material">
        <color rgba="0.152941 0.152941 0.152941 1"/>
      </material>
    </visual>
    <collision>
      <origin xyz="0 -6.93889e-18 0.01625" rpy="1.5708 2.77556e-17 -5.55112e-17"/>
      <geometry>
        <mesh filename="package://meshes/wheel4_omniwheel_tyre_v1.stl"/>
      </geometry>
    </collision>
  </link>
  <!-- Joint from wheel4_shaft_holder_v2_2 to wheel4_omniwheel_tyre_v1_35 -->
  <joint name="wheel_f" type="continuous">
    <origin xyz="-0.0384102 0.0124802 0.0065" rpy="1.5708 -0.947246 2.82743"/>
    <parent link="wheel4_shaft_holder_v2_2"/>
    <child link="wheel4_omniwheel_tyre_v1_35"/>
    <axis xyz="0 0 1"/>
    <limit effort="5" velocity="10"/>
    <joint_properties friction="0.1"/>
  </joint>
  <!-- Link wheel4_omniwheel_tyre_v1_36 -->
  <link name="wheel4_omniwheel_tyre_v1_36">
    <inertial>
      <origin xyz="-6.93633e-10 1.43522e-17 1.35567e-09" rpy="0 0 0"/>
      <mass value="0.00502735"/>
      <inertia ixx="2.29535e-07" ixy="5.0967e-23" ixz="8.11134e-13" iyy="2.29535e-07" iyz="6.45897e-24" izz="2.32706e-07"/>
    </inertial>
    <!-- Part wheel4_omniwheel_tyre_v1_36 -->
    <visual>
      <origin xyz="-1.38778e-17 1.38778e-17 0.01625" rpy="1.5708 8.32667e-17 1.11022e-16"/>
      <geometry>
        <mesh filename="package://meshes/wheel4_omniwheel_tyre_v1.stl"/>
      </geometry>
      <material name="wheel4_omniwheel_tyre_v1_36_material">
        <color rgba="0.152941 0.152941 0.152941 1"/>
      </material>
    </visual>
    <collision>
      <origin xyz="-1.38778e-17 1.38778e-17 0.01625" rpy="1.5708 8.32667e-17 1.11022e-16"/>
      <geometry>
        <mesh filename="package://meshes/wheel4_omniwheel_tyre_v1.stl"/>
      </geometry>
    </collision>
  </link>
  <!-- Joint from wheel4_shaft_holder_v2_2 to wheel4_omniwheel_tyre_v1_36 -->
  <joint name="wheel_e" type="continuous">
    <origin xyz="-0.0384102 -0.0124802 0.0065" rpy="1.5708 -0.971379 0.314159"/>
    <parent link="wheel4_shaft_holder_v2_2"/>
    <child link="wheel4_omniwheel_tyre_v1_36"/>
    <axis xyz="0 0 1"/>
    <limit effort="5" velocity="10"/>
    <joint_properties friction="0.1"/>
  </joint>
  <!-- Link wheel4_omniwheel_tyre_v1_37 -->
  <link name="wheel4_omniwheel_tyre_v1_37">
    <inertial>
      <origin xyz="-6.93633e-10 6.99912e-19 1.35567e-09" rpy="0 0 0"/>
      <mass value="0.00502735"/>
      <inertia ixx="2.29535e-07" ixy="-1.75199e-23" ixz="8.11134e-13" iyy="2.29535e-07" iyz="4.39787e-26" izz="2.32706e-07"/>
    </inertial>
    <!-- Part wheel4_omniwheel_tyre_v1_37 -->
    <visual>
      <origin xyz="-3.46945e-18 0 0.01625" rpy="1.5708 -0 -2.77556e-17"/>
      <geometry>
        <mesh filename="package://meshes/wheel4_omniwheel_tyre_v1.stl"/>
      </geometry>
      <material name="wheel4_omniwheel_tyre_v1_37_material">
        <color rgba="0.152941 0.152941 0.152941 1"/>
      </material>
    </visual>
    <collision>
      <origin xyz="-3.46945e-18 0 0.01625" rpy="1.5708 -0 -2.77556e-17"/>
      <geometry>
        <mesh filename="package://meshes/wheel4_omniwheel_tyre_v1.stl"/>
      </geometry>
    </collision>
  </link>
  <!-- Joint from wheel4_shaft_holder_v2_2 to wheel4_omniwheel_tyre_v1_37 -->
  <joint name="wheel_d" type="continuous">
    <origin xyz="-0.0237388 -0.0326737 0.0065" rpy="1.5708 -0.180277 0.942478"/>
    <parent link="wheel4_shaft_holder_v2_2"/>
    <child link="wheel4_omniwheel_tyre_v1_37"/>
    <axis xyz="0 0 1"/>
    <limit effort="5" velocity="10"/>
    <joint_properties friction="0.1"/>
  </joint>
  <!-- Link wheel4_omniwheel_tyre_v1_38 -->
  <link name="wheel4_omniwheel_tyre_v1_38">
    <inertial>
      <origin xyz="-6.93633e-10 1.44771e-17 1.35567e-09" rpy="0 0 0"/>
      <mass value="0.00502735"/>
      <inertia ixx="2.29535e-07" ixy="1.62789e-29" ixz="8.11134e-13" iyy="2.29535e-07" iyz="6.3632e-26" izz="2.32706e-07"/>
    </inertial>
    <!-- Part wheel4_omniwheel_tyre_v1_38 -->
    <visual>
      <origin xyz="0 1.38778e-17 0.01625" rpy="1.5708 5.20093e-17 5.38162e-33"/>
      <geometry>
        <mesh filename="package://meshes/wheel4_omniwheel_tyre_v1.stl"/>
      </geometry>
      <material name="wheel4_omniwheel_tyre_v1_38_material">
        <color rgba="0.152941 0.152941 0.152941 1"/>
      </material>
    </visual>
    <collision>
      <origin xyz="0 1.38778e-17 0.01625" rpy="1.5708 5.20093e-17 5.38162e-33"/>
      <geometry>
        <mesh filename="package://meshes/wheel4_omniwheel_tyre_v1.stl"/>
      </geometry>
    </collision>
  </link>
  <!-- Joint from wheel4_shaft_holder_v2_2 to wheel4_omniwheel_tyre_v1_38 -->
  <joint name="wheel_c" type="continuous">
    <origin xyz="0 -0.0403869 0.0065" rpy="1.5708 6.10623e-16 1.5708"/>
    <parent link="wheel4_shaft_holder_v2_2"/>
    <child link="wheel4_omniwheel_tyre_v1_38"/>
    <axis xyz="0 0 1"/>
    <limit effort="5" velocity="10"/>
    <joint_properties friction="0.1"/>
  </joint>
  <!-- Link wheel4_omniwheel_tyre_v1_39 -->
  <link name="wheel4_omniwheel_tyre_v1_39">
    <inertial>
      <origin xyz="-6.93633e-10 1.45777e-17 1.35567e-09" rpy="0 0 0"/>
      <mass value="0.00502735"/>
      <inertia ixx="2.29535e-07" ixy="3.18545e-24" ixz="8.11134e-13" iyy="2.29535e-07" iyz="4.39899e-26" izz="2.32706e-07"/>
    </inertial>
    <!-- Part wheel4_omniwheel_tyre_v1_39 -->
    <visual>
      <origin xyz="-3.46945e-18 1.38778e-17 0.01625" rpy="1.5708 5.55112e-17 -1.38778e-17"/>
      <geometry>
        <mesh filename="package://meshes/wheel4_omniwheel_tyre_v1.stl"/>
      </geometry>
      <material name="wheel4_omniwheel_tyre_v1_39_material">
        <color rgba="0.152941 0.152941 0.152941 1"/>
      </material>
    </visual>
    <collision>
      <origin xyz="-3.46945e-18 1.38778e-17 0.01625" rpy="1.5708 5.55112e-17 -1.38778e-17"/>
      <geometry>
        <mesh filename="package://meshes/wheel4_omniwheel_tyre_v1.stl"/>
      </geometry>
    </collision>
  </link>
  <!-- Joint from wheel4_shaft_holder_v2_2 to wheel4_omniwheel_tyre_v1_39 -->
  <joint name="wheel_b" type="continuous">
    <origin xyz="0.0237388 -0.0326737 0.0065" rpy="1.5708 -0.210366 2.19911"/>
    <parent link="wheel4_shaft_holder_v2_2"/>
    <child link="wheel4_omniwheel_tyre_v1_39"/>
    <axis xyz="0 0 1"/>
    <limit effort="5" velocity="10"/>
    <joint_properties friction="0.1"/>
  </joint>
  <!-- Link wheel4_omniwheel_tyre_v1_40 -->
  <link name="wheel4_omniwheel_tyre_v1_40">
    <inertial>
      <origin xyz="5.72708e-10 -3.91321e-10 1.35567e-09" rpy="0 0 0"/>
      <mass value="0.00502735"/>
      <inertia ixx="2.29535e-07" ixy="-1.0985e-21" ixz="-6.69724e-13" iyy="2.29535e-07" iyz="4.5761e-13" izz="2.32706e-07"/>
    </inertial>
    <!-- Part wheel4_omniwheel_tyre_v1_40 -->
    <visual>
      <origin xyz="-1.38778e-17 -1.38778e-17 0.01625" rpy="1.5708 8.32667e-17 2.54218"/>
      <geometry>
        <mesh filename="package://meshes/wheel4_omniwheel_tyre_v1.stl"/>
      </geometry>
      <material name="wheel4_omniwheel_tyre_v1_40_material">
        <color rgba="0.152941 0.152941 0.152941 1"/>
      </material>
    </visual>
    <collision>
      <origin xyz="-1.38778e-17 -1.38778e-17 0.01625" rpy="1.5708 8.32667e-17 2.54218"/>
      <geometry>
        <mesh filename="package://meshes/wheel4_omniwheel_tyre_v1.stl"/>
      </geometry>
    </collision>
  </link>
  <!-- Joint from wheel4_shaft_holder_v2_2 to wheel4_omniwheel_tyre_v1_40 -->
  <joint name="wheel_a" type="continuous">
    <origin xyz="0.0384102 -0.0124802 0.0065" rpy="-1.25664 1.5708 0"/>
    <parent link="wheel4_shaft_holder_v2_2"/>
    <child link="wheel4_omniwheel_tyre_v1_40"/>
    <axis xyz="0 0 1"/>
    <limit effort="5" velocity="10"/>
    <joint_properties friction="0.1"/>
  </joint>
  <!-- Joint from part_1 to wheel4_shaft_holder_v2_2 -->
  <joint name="wheel_motorA" type="continuous">
    <origin xyz="6.36065e-18 0.105 0.0125" rpy="-1.5708 -1.5708 0"/>
    <parent link="part_1"/>
    <child link="wheel4_shaft_holder_v2_2"/>
    <axis xyz="0 0 1"/>
    <limit effort="5" velocity="10"/>
    <joint_properties friction="0.1"/>
  </joint>
  <!-- Link wheel4_shaft_holder_v2_3 -->
  <link name="wheel4_shaft_holder_v2_3">
    <inertial>
      <origin xyz="3.57042e-13 3.57045e-13 0.0159932" rpy="0 0 0"/>
      <mass value="0.162524"/>
      <inertia ixx="0.000106018" ixy="-1.53476e-20" ixz="-4.58451e-15" iyy="0.000106018" iyz="-5.68706e-15" izz="0.000180425"/>
    </inertial>
    <!-- Part wheel4_shaft_omni_v1_41 -->
    <!-- Part wheel4_shaft_omni_v1_42 -->
    <!-- Part wheel4_shaft_omni_v1_43 -->
    <!-- Part wheel4_shaft_omni_v1_44 -->
    <!-- Part wheel4_shaft_omni_v1_45 -->
    <!-- Part wheel4_shaft_omni_v1_46 -->
    <!-- Part wheel4_shaft_omni_v1_47 -->
    <!-- Part wheel4_shaft_omni_v1_48 -->
    <!-- Part wheel4_shaft_omni_v1_49 -->
    <!-- Part wheel4_shaft_omni_v1_50 -->
    <!-- Part wheel4_body_omni_v4_5 -->
    <visual>
      <origin xyz="0 2.46519e-32 0.013" rpy="1.5708 1.5708 0"/>
      <geometry>
        <mesh filename="package://meshes/wheel4_body_omni_v4__2.stl"/>
      </geometry>
      <material name="wheel4_body_omni_v4_5_material">
        <color rgba="0.627451 0.627451 0.627451 1"/>
      </material>
    </visual>
    <!-- Part wheel4_shaft_omni_v1_51 -->
    <!-- Part wheel4_shaft_omni_v1_52 -->
    <!-- Part wheel4_shaft_omni_v1_53 -->
    <!-- Part wheel4_shaft_omni_v1_54 -->
    <!-- Part wheel4_shaft_omni_v1_55 -->
    <!-- Part wheel4_shaft_omni_v1_56 -->
    <!-- Part wheel4_shaft_omni_v1_57 -->
    <!-- Part wheel4_shaft_omni_v1_58 -->
    <!-- Part wheel4_shaft_omni_v1_59 -->
    <!-- Part wheel4_shaft_holder_v2_3 -->
    <visual>
      <origin xyz="-5.20417e-18 -3.75857e-18 0.013" rpy="1.5708 -1.5708 0"/>
      <geometry>
        <mesh filename="package://meshes/wheel4_shaft_holder_v2.stl"/>
      </geometry>
      <material name="wheel4_shaft_holder_v2_3_material">
        <color rgba="0.627451 0.627451 0.627451 1"/>
      </material>
    </visual>
    <!-- Part wheel4_shaft_omni_v1_60 -->
    <!-- Part wheel4_body_omni_v4_6 -->
    <visual>
      <origin xyz="-1.9082e-17 -6.97588e-18 0.032" rpy="-6.22065e-16 1.5708 0"/>
      <geometry>
        <mesh filename="package://meshes/wheel4_body_omni_v4.stl"/>
      </geometry>
      <material name="wheel4_body_omni_v4_6_material">
        <color rgba="0.627451 0.627451 0.627451 1"/>
      </material>
    </visual>
  </link>
  <!-- Frame motorD (dummy link + fixed joint) -->
  <link name="motorD">
    <origin xyz="0 0 0" rpy="0 -0 0"/>
    <inertial>
      <origin xyz="0 0 0" rpy="0 0 0"/>
      <mass value="1e-9"/>
      <inertia ixx="0" ixy="0" ixz="0" iyy="0" iyz="0" izz="0"/>
    </inertial>
  </link>
  <joint name="motorD_frame" type="fixed">
    <origin xyz="0 -1.53081e-19 0" rpy="3.14159 -5.04871e-29 3.14159"/>
    <parent link="wheel4_shaft_holder_v2_3"/>
    <child link="motorD"/>
    <axis xyz="0 0 0"/>
  </joint>
  <!-- Link wheel4_omniwheel_tyre_v1_41 -->
  <link name="wheel4_omniwheel_tyre_v1_41">
    <inertial>
      <origin xyz="-6.93633e-10 5.993e-19 1.35567e-09" rpy="0 0 0"/>
      <mass value="0.00502735"/>
      <inertia ixx="2.29535e-07" ixy="1.62789e-29" ixz="8.11134e-13" iyy="2.29535e-07" iyz="6.3632e-26" izz="2.32706e-07"/>
    </inertial>
    <!-- Part wheel4_omniwheel_tyre_v1_41 -->
    <visual>
      <origin xyz="0 0 0.01625" rpy="1.5708 5.20093e-17 -6.0505e-50"/>
      <geometry>
        <mesh filename="package://meshes/wheel4_omniwheel_tyre_v1.stl"/>
      </geometry>
      <material name="wheel4_omniwheel_tyre_v1_41_material">
        <color rgba="0.152941 0.152941 0.152941 1"/>
      </material>
    </visual>
    <collision>
      <origin xyz="0 0 0.01625" rpy="1.5708 5.20093e-17 -6.0505e-50"/>
      <geometry>
        <mesh filename="package://meshes/wheel4_omniwheel_tyre_v1.stl"/>
      </geometry>
    </collision>
  </link>
  <!-- Joint from wheel4_shaft_holder_v2_3 to wheel4_omniwheel_tyre_v1_41 -->
  <joint name="wheel_4k" type="continuous">
    <origin xyz="-0.0403869 1.74979e-17 0.0255" rpy="-1.5708 1.5708 0"/>
    <parent link="wheel4_shaft_holder_v2_3"/>
    <child link="wheel4_omniwheel_tyre_v1_41"/>
    <axis xyz="0 0 1"/>
    <limit effort="5" velocity="10"/>
    <joint_properties friction="0.1"/>
  </joint>
  <!-- Link wheel4_omniwheel_tyre_v1_42 -->
  <link name="wheel4_omniwheel_tyre_v1_42">
    <inertial>
      <origin xyz="-6.93633e-10 3.49282e-18 1.35567e-09" rpy="0 0 0"/>
      <mass value="0.00502735"/>
      <inertia ixx="2.29535e-07" ixy="4.5027e-29" ixz="8.11134e-13" iyy="2.29535e-07" iyz="2.56595e-23" izz="2.32706e-07"/>
    </inertial>
    <!-- Part wheel4_omniwheel_tyre_v1_42 -->
    <visual>
      <origin xyz="-2.77556e-17 3.46945e-18 0.01625" rpy="1.5708 5.20093e-17 -1.97215e-31"/>
      <geometry>
        <mesh filename="package://meshes/wheel4_omniwheel_tyre_v1.stl"/>
      </geometry>
      <material name="wheel4_omniwheel_tyre_v1_42_material">
        <color rgba="0.152941 0.152941 0.152941 1"/>
      </material>
    </visual>
    <collision>
      <origin xyz="-2.77556e-17 3.46945e-18 0.01625" rpy="1.5708 5.20093e-17 -1.97215e-31"/>
      <geometry>
        <mesh filename="package://meshes/wheel4_omniwheel_tyre_v1.stl"/>
      </geometry>
    </collision>
  </link>
  <!-- Joint from wheel4_shaft_holder_v2_3 to wheel4_omniwheel_tyre_v1_42 -->
  <joint name="wheel_4l" type="continuous">
    <origin xyz="-0.0326737 0.0237388 0.0255" rpy="-0.942478 1.5708 0"/>
    <parent link="wheel4_shaft_holder_v2_3"/>
    <child link="wheel4_omniwheel_tyre_v1_42"/>
    <axis xyz="0 0 1"/>
    <limit effort="5" velocity="10"/>
    <joint_properties friction="0.1"/>
  </joint>
  <!-- Link wheel4_omniwheel_tyre_v1_43 -->
  <link name="wheel4_omniwheel_tyre_v1_43">
    <inertial>
      <origin xyz="-6.93633e-10 -1.29524e-17 1.35567e-09" rpy="0 0 0"/>
      <mass value="0.00502735"/>
      <inertia ixx="2.29535e-07" ixy="-5.65847e-39" ixz="8.11134e-13" iyy="2.29535e-07" iyz="1.9996e-44" izz="2.32706e-07"/>
    </inertial>
    <!-- Part wheel4_omniwheel_tyre_v1_43 -->
    <visual>
      <origin xyz="0 -1.38778e-17 0.01625" rpy="1.5708 5.20093e-17 2.46519e-32"/>
      <geometry>
        <mesh filename="package://meshes/wheel4_omniwheel_tyre_v1.stl"/>
      </geometry>
      <material name="wheel4_omniwheel_tyre_v1_43_material">
        <color rgba="0.152941 0.152941 0.152941 1"/>
      </material>
    </visual>
    <collision>
      <origin xyz="0 -1.38778e-17 0.01625" rpy="1.5708 5.20093e-17 2.46519e-32"/>
      <geometry>
        <mesh filename="package://meshes/wheel4_omniwheel_tyre_v1.stl"/>
      </geometry>
    </collision>
  </link>
  <!-- Joint from wheel4_shaft_holder_v2_3 to wheel4_omniwheel_tyre_v1_43 -->
  <joint name="wheel_4m" type="continuous">
    <origin xyz="-0.0124802 0.0384102 0.0255" rpy="-0.314159 1.5708 0"/>
    <parent link="wheel4_shaft_holder_v2_3"/>
    <child link="wheel4_omniwheel_tyre_v1_43"/>
    <axis xyz="0 0 1"/>
    <limit effort="5" velocity="10"/>
    <joint_properties friction="0.1"/>
  </joint>
  <!-- Link wheel4_omniwheel_tyre_v1_44 -->
  <link name="wheel4_omniwheel_tyre_v1_44">
    <inertial>
      <origin xyz="-6.93633e-10 9.25426e-19 1.35567e-09" rpy="0 0 0"/>
      <mass value="0.00502735"/>
      <inertia ixx="2.29535e-07" ixy="0" ixz="8.11134e-13" iyy="2.29535e-07" iyz="0" izz="2.32706e-07"/>
    </inertial>
    <!-- Part wheel4_omniwheel_tyre_v1_44 -->
    <visual>
      <origin xyz="0 0 0.01625" rpy="1.5708 5.20093e-17 0"/>
      <geometry>
        <mesh filename="package://meshes/wheel4_omniwheel_tyre_v1.stl"/>
      </geometry>
      <material name="wheel4_omniwheel_tyre_v1_44_material">
        <color rgba="0.152941 0.152941 0.152941 1"/>
      </material>
    </visual>
    <collision>
      <origin xyz="0 0 0.01625" rpy="1.5708 5.20093e-17 0"/>
      <geometry>
        <mesh filename="package://meshes/wheel4_omniwheel_tyre_v1.stl"/>
      </geometry>
    </collision>
  </link>
  <!-- Joint from wheel4_shaft_holder_v2_3 to wheel4_omniwheel_tyre_v1_44 -->
  <joint name="wheel_4n" type="continuous">
    <origin xyz="0.0124802 0.0384102 0.0255" rpy="-2.82743 1.5708 0"/>
    <parent link="wheel4_shaft_holder_v2_3"/>
    <child link="wheel4_omniwheel_tyre_v1_44"/>
    <axis xyz="0 0 1"/>
    <limit effort="5" velocity="10"/>
    <joint_properties friction="0.1"/>
  </joint>
  <!-- Link wheel4_omniwheel_tyre_v1_45 -->
  <link name="wheel4_omniwheel_tyre_v1_45">
    <inertial>
      <origin xyz="-6.93633e-10 9.25426e-19 1.35567e-09" rpy="0 0 0"/>
      <mass value="0.00502735"/>
      <inertia ixx="2.29535e-07" ixy="1.81071e-37" ixz="8.11134e-13" iyy="2.29535e-07" iyz="1.27417e-23" izz="2.32706e-07"/>
    </inertial>
    <!-- Part wheel4_omniwheel_tyre_v1_45 -->
    <visual>
      <origin xyz="-2.77556e-17 0 0.01625" rpy="1.5708 5.20093e-17 3.9443e-31"/>
      <geometry>
        <mesh filename="package://meshes/wheel4_omniwheel_tyre_v1.stl"/>
      </geometry>
      <material name="wheel4_omniwheel_tyre_v1_45_material">
        <color rgba="0.152941 0.152941 0.152941 1"/>
      </material>
    </visual>
    <collision>
      <origin xyz="-2.77556e-17 0 0.01625" rpy="1.5708 5.20093e-17 3.9443e-31"/>
      <geometry>
        <mesh filename="package://meshes/wheel4_omniwheel_tyre_v1.stl"/>
      </geometry>
    </collision>
  </link>
  <!-- Joint from wheel4_shaft_holder_v2_3 to wheel4_omniwheel_tyre_v1_45 -->
  <joint name="wheel_4o" type="continuous">
    <origin xyz="0.0326737 0.0237388 0.0255" rpy="-2.19911 1.5708 0"/>
    <parent link="wheel4_shaft_holder_v2_3"/>
    <child link="wheel4_omniwheel_tyre_v1_45"/>
    <axis xyz="0 0 1"/>
    <limit effort="5" velocity="10"/>
    <joint_properties friction="0.1"/>
  </joint>
  <!-- Link wheel4_omniwheel_tyre_v1_46 -->
  <link name="wheel4_omniwheel_tyre_v1_46">
    <inertial>
      <origin xyz="-6.93633e-10 5.993e-19 1.35567e-09" rpy="0 0 0"/>
      <mass value="0.00502735"/>
      <inertia ixx="2.29535e-07" ixy="1.62789e-29" ixz="8.11134e-13" iyy="2.29535e-07" iyz="6.3632e-26" izz="2.32706e-07"/>
    </inertial>
    <!-- Part wheel4_omniwheel_tyre_v1_46 -->
    <visual>
      <origin xyz="0 0 0.01625" rpy="1.5708 5.20093e-17 -1.05199e-50"/>
      <geometry>
        <mesh filename="package://meshes/wheel4_omniwheel_tyre_v1.stl"/>
      </geometry>
      <material name="wheel4_omniwheel_tyre_v1_46_material">
        <color rgba="0.152941 0.152941 0.152941 1"/>
      </material>
    </visual>
    <collision>
      <origin xyz="0 0 0.01625" rpy="1.5708 5.20093e-17 -1.05199e-50"/>
      <geometry>
        <mesh filename="package://meshes/wheel4_omniwheel_tyre_v1.stl"/>
      </geometry>
    </collision>
  </link>
  <!-- Joint from wheel4_shaft_holder_v2_3 to wheel4_omniwheel_tyre_v1_46 -->
  <joint name="wheel_4p" type="continuous">
    <origin xyz="0.0403869 2.44368e-17 0.0255" rpy="-1.5708 1.5708 0"/>
    <parent link="wheel4_shaft_holder_v2_3"/>
    <child link="wheel4_omniwheel_tyre_v1_46"/>
    <axis xyz="0 0 1"/>
    <limit effort="5" velocity="10"/>
    <joint_properties friction="0.1"/>
  </joint>
  <!-- Link wheel4_omniwheel_tyre_v1_47 -->
  <link name="wheel4_omniwheel_tyre_v1_47">
    <inertial>
      <origin xyz="-6.93633e-10 -6.01347e-18 1.35567e-09" rpy="0 0 0"/>
      <mass value="0.00502735"/>
      <inertia ixx="2.29535e-07" ixy="2.26339e-38" ixz="8.11134e-13" iyy="2.29535e-07" iyz="-1.27417e-23" izz="2.32706e-07"/>
    </inertial>
    <!-- Part wheel4_omniwheel_tyre_v1_47 -->
    <visual>
      <origin xyz="-2.77556e-17 -6.93889e-18 0.01625" rpy="1.5708 5.20093e-17 0"/>
      <geometry>
        <mesh filename="package://meshes/wheel4_omniwheel_tyre_v1.stl"/>
      </geometry>
      <material name="wheel4_omniwheel_tyre_v1_47_material">
        <color rgba="0.152941 0.152941 0.152941 1"/>
      </material>
    </visual>
    <collision>
      <origin xyz="-2.77556e-17 -6.93889e-18 0.01625" rpy="1.5708 5.20093e-17 0"/>
      <geometry>
        <mesh filename="package://meshes/wheel4_omniwheel_tyre_v1.stl"/>
      </geometry>
    </collision>
  </link>
  <!-- Joint from wheel4_shaft_holder_v2_3 to wheel4_omniwheel_tyre_v1_47 -->
  <joint name="wheel_4q" type="continuous">
    <origin xyz="0.0326737 -0.0237388 0.0255" rpy="-0.942478 1.5708 0"/>
    <parent link="wheel4_shaft_holder_v2_3"/>
    <child link="wheel4_omniwheel_tyre_v1_47"/>
    <axis xyz="0 0 1"/>
    <limit effort="5" velocity="10"/>
    <joint_properties friction="0.1"/>
  </joint>
  <!-- Link wheel4_omniwheel_tyre_v1_48 -->
  <link name="wheel4_omniwheel_tyre_v1_48">
    <inertial>
      <origin xyz="-6.93633e-10 1.39012e-17 1.35567e-09" rpy="0 0 0"/>
      <mass value="0.00502735"/>
      <inertia ixx="2.29535e-07" ixy="4.77816e-23" ixz="8.11134e-13" iyy="2.29535e-07" iyz="1.76067e-25" izz="2.32706e-07"/>
    </inertial>
    <!-- Part wheel4_omniwheel_tyre_v1_48 -->
    <visual>
      <origin xyz="0 1.38778e-17 0.01625" rpy="1.5708 2.77556e-17 7.63278e-17"/>
      <geometry>
        <mesh filename="package://meshes/wheel4_omniwheel_tyre_v1.stl"/>
      </geometry>
      <material name="wheel4_omniwheel_tyre_v1_48_material">
        <color rgba="0.152941 0.152941 0.152941 1"/>
      </material>
    </visual>
    <collision>
      <origin xyz="0 1.38778e-17 0.01625" rpy="1.5708 2.77556e-17 7.63278e-17"/>
      <geometry>
        <mesh filename="package://meshes/wheel4_omniwheel_tyre_v1.stl"/>
      </geometry>
    </collision>
  </link>
  <!-- Joint from wheel4_shaft_holder_v2_3 to wheel4_omniwheel_tyre_v1_48 -->
  <joint name="wheel_4r" type="continuous">
    <origin xyz="0.0124802 -0.0384102 0.0255" rpy="-1.5708 1.00644 -1.25664"/>
    <parent link="wheel4_shaft_holder_v2_3"/>
    <child link="wheel4_omniwheel_tyre_v1_48"/>
    <axis xyz="0 0 1"/>
    <limit effort="5" velocity="10"/>
    <joint_properties friction="0.1"/>
  </joint>
  <!-- Link wheel4_omniwheel_tyre_v1_49 -->
  <link name="wheel4_omniwheel_tyre_v1_49">
    <inertial>
      <origin xyz="-6.93633e-10 7.86432e-18 1.35567e-09" rpy="0 0 0"/>
      <mass value="0.00502735"/>
      <inertia ixx="2.29535e-07" ixy="0" ixz="8.11134e-13" iyy="2.29535e-07" iyz="0" izz="2.32706e-07"/>
    </inertial>
    <!-- Part wheel4_omniwheel_tyre_v1_49 -->
    <visual>
      <origin xyz="0 6.93889e-18 0.01625" rpy="1.5708 5.20093e-17 0"/>
      <geometry>
        <mesh filename="package://meshes/wheel4_omniwheel_tyre_v1.stl"/>
      </geometry>
      <material name="wheel4_omniwheel_tyre_v1_49_material">
        <color rgba="0.152941 0.152941 0.152941 1"/>
      </material>
    </visual>
    <collision>
      <origin xyz="0 6.93889e-18 0.01625" rpy="1.5708 5.20093e-17 0"/>
      <geometry>
        <mesh filename="package://meshes/wheel4_omniwheel_tyre_v1.stl"/>
      </geometry>
    </collision>
  </link>
  <!-- Joint from wheel4_shaft_holder_v2_3 to wheel4_omniwheel_tyre_v1_49 -->
  <joint name="wheel_4s" type="continuous">
    <origin xyz="-0.0124802 -0.0384102 0.0255" rpy="-2.82743 1.5708 0"/>
    <parent link="wheel4_shaft_holder_v2_3"/>
    <child link="wheel4_omniwheel_tyre_v1_49"/>
    <axis xyz="0 0 1"/>
    <limit effort="5" velocity="10"/>
    <joint_properties friction="0.1"/>
  </joint>
  <!-- Link wheel4_omniwheel_tyre_v1_50 -->
  <link name="wheel4_omniwheel_tyre_v1_50">
    <inertial>
      <origin xyz="-6.93633e-10 9.25426e-19 1.35567e-09" rpy="0 0 0"/>
      <mass value="0.00502735"/>
      <inertia ixx="2.29535e-07" ixy="2.71607e-37" ixz="8.11134e-13" iyy="2.29535e-07" iyz="6.39872e-43" izz="2.32706e-07"/>
    </inertial>
    <!-- Part wheel4_omniwheel_tyre_v1_50 -->
    <visual>
      <origin xyz="-2.77556e-17 0 0.01625" rpy="1.5708 5.20093e-17 7.88861e-31"/>
      <geometry>
        <mesh filename="package://meshes/wheel4_omniwheel_tyre_v1.stl"/>
      </geometry>
      <material name="wheel4_omniwheel_tyre_v1_50_material">
        <color rgba="0.152941 0.152941 0.152941 1"/>
      </material>
    </visual>
    <collision>
      <origin xyz="-2.77556e-17 0 0.01625" rpy="1.5708 5.20093e-17 7.88861e-31"/>
      <geometry>
        <mesh filename="package://meshes/wheel4_omniwheel_tyre_v1.stl"/>
      </geometry>
    </collision>
  </link>
  <!-- Joint from wheel4_shaft_holder_v2_3 to wheel4_omniwheel_tyre_v1_50 -->
  <joint name="wheel_4t" type="continuous">
    <origin xyz="-0.0326737 -0.0237388 0.0255" rpy="-2.19911 1.5708 0"/>
    <parent link="wheel4_shaft_holder_v2_3"/>
    <child link="wheel4_omniwheel_tyre_v1_50"/>
    <axis xyz="0 0 1"/>
    <limit effort="5" velocity="10"/>
    <joint_properties friction="0.1"/>
  </joint>
  <!-- Link wheel4_omniwheel_tyre_v1_51 -->
  <link name="wheel4_omniwheel_tyre_v1_51">
    <inertial>
      <origin xyz="-6.93633e-10 -9.25426e-19 -1.46309e-09" rpy="0 0 0"/>
      <mass value="0.00502735"/>
      <inertia ixx="2.29535e-07" ixy="3.62142e-37" ixz="-8.11134e-13" iyy="2.29535e-07" iyz="-1.27974e-42" izz="2.32706e-07"/>
    </inertial>
    <!-- Part wheel4_omniwheel_tyre_v1_51 -->
    <visual>
      <origin xyz="0 0 -0.01625" rpy="-1.5708 3.9443e-31 1.57772e-30"/>
      <geometry>
        <mesh filename="package://meshes/wheel4_omniwheel_tyre_v1.stl"/>
      </geometry>
      <material name="wheel4_omniwheel_tyre_v1_51_material">
        <color rgba="0.152941 0.152941 0.152941 1"/>
      </material>
    </visual>
    <collision>
      <origin xyz="0 0 -0.01625" rpy="-1.5708 3.9443e-31 1.57772e-30"/>
      <geometry>
        <mesh filename="package://meshes/wheel4_omniwheel_tyre_v1.stl"/>
      </geometry>
    </collision>
  </link>
  <!-- Joint from wheel4_shaft_holder_v2_3 to wheel4_omniwheel_tyre_v1_51 -->
  <joint name="wheel_4j" type="continuous">
    <origin xyz="0.0384102 0.0124802 0.0065" rpy="-1.88496 1.5708 0"/>
    <parent link="wheel4_shaft_holder_v2_3"/>
    <child link="wheel4_omniwheel_tyre_v1_51"/>
    <axis xyz="0 0 1"/>
    <limit effort="5" velocity="10"/>
    <joint_properties friction="0.1"/>
  </joint>
  <!-- Link wheel4_omniwheel_tyre_v1_52 -->
  <link name="wheel4_omniwheel_tyre_v1_52">
    <inertial>
      <origin xyz="-6.93633e-10 -6.91552e-18 1.35567e-09" rpy="0 0 0"/>
      <mass value="0.00502735"/>
      <inertia ixx="2.29535e-07" ixy="4.5027e-29" ixz="8.11134e-13" iyy="2.29535e-07" iyz="1.76005e-25" izz="2.32706e-07"/>
    </inertial>
    <!-- Part wheel4_omniwheel_tyre_v1_52 -->
    <visual>
      <origin xyz="0 -6.93889e-18 0.01625" rpy="1.5708 5.20093e-17 0"/>
      <geometry>
        <mesh filename="package://meshes/wheel4_omniwheel_tyre_v1.stl"/>
      </geometry>
      <material name="wheel4_omniwheel_tyre_v1_52_material">
        <color rgba="0.152941 0.152941 0.152941 1"/>
      </material>
    </visual>
    <collision>
      <origin xyz="0 -6.93889e-18 0.01625" rpy="1.5708 5.20093e-17 0"/>
      <geometry>
        <mesh filename="package://meshes/wheel4_omniwheel_tyre_v1.stl"/>
      </geometry>
    </collision>
  </link>
  <!-- Joint from wheel4_shaft_holder_v2_3 to wheel4_omniwheel_tyre_v1_52 -->
  <joint name="wheel_4i" type="continuous">
    <origin xyz="0.0237388 0.0326737 0.0065" rpy="0.628319 1.5708 0"/>
    <parent link="wheel4_shaft_holder_v2_3"/>
    <child link="wheel4_omniwheel_tyre_v1_52"/>
    <axis xyz="0 0 1"/>
    <limit effort="5" velocity="10"/>
    <joint_properties friction="0.1"/>
  </joint>
  <!-- Link wheel4_omniwheel_tyre_v1_53 -->
  <link name="wheel4_omniwheel_tyre_v1_53">
    <inertial>
      <origin xyz="-6.93633e-10 5.99299e-19 1.35567e-09" rpy="0 0 0"/>
      <mass value="0.00502735"/>
      <inertia ixx="2.29535e-07" ixy="-1.11657e-24" ixz="8.11134e-13" iyy="2.29535e-07" iyz="6.4459e-26" izz="2.32706e-07"/>
    </inertial>
    <!-- Part wheel4_omniwheel_tyre_v1_53 -->
    <visual>
      <origin xyz="0 0 0.01625" rpy="1.5708 6.69808e-17 1.01953e-15"/>
      <geometry>
        <mesh filename="package://meshes/wheel4_omniwheel_tyre_v1.stl"/>
      </geometry>
      <material name="wheel4_omniwheel_tyre_v1_53_material">
        <color rgba="0.152941 0.152941 0.152941 1"/>
      </material>
    </visual>
    <collision>
      <origin xyz="0 0 0.01625" rpy="1.5708 6.69808e-17 1.01953e-15"/>
      <geometry>
        <mesh filename="package://meshes/wheel4_omniwheel_tyre_v1.stl"/>
      </geometry>
    </collision>
  </link>
  <!-- Joint from wheel4_shaft_holder_v2_3 to wheel4_omniwheel_tyre_v1_53 -->
  <joint name="wheel_4h" type="continuous">
    <origin xyz="3.46945e-18 0.0403869 0.0065" rpy="-4.44089e-16 1.5708 0"/>
    <parent link="wheel4_shaft_holder_v2_3"/>
    <child link="wheel4_omniwheel_tyre_v1_53"/>
    <axis xyz="0 0 1"/>
    <limit effort="5" velocity="10"/>
    <joint_properties friction="0.1"/>
  </joint>
  <!-- Link wheel4_omniwheel_tyre_v1_54 -->
  <link name="wheel4_omniwheel_tyre_v1_54">
    <inertial>
      <origin xyz="-6.93633e-10 6.06021e-18 1.35567e-09" rpy="0 0 0"/>
      <mass value="0.00502735"/>
      <inertia ixx="2.29535e-07" ixy="9.00539e-29" ixz="8.11134e-13" iyy="2.29535e-07" iyz="2.58355e-23" izz="2.32706e-07"/>
    </inertial>
    <!-- Part wheel4_omniwheel_tyre_v1_54 -->
    <visual>
      <origin xyz="0 6.93889e-18 0.01625" rpy="1.5708 5.20093e-17 0"/>
      <geometry>
        <mesh filename="package://meshes/wheel4_omniwheel_tyre_v1.stl"/>
      </geometry>
      <material name="wheel4_omniwheel_tyre_v1_54_material">
        <color rgba="0.152941 0.152941 0.152941 1"/>
      </material>
    </visual>
    <collision>
      <origin xyz="0 6.93889e-18 0.01625" rpy="1.5708 5.20093e-17 0"/>
      <geometry>
        <mesh filename="package://meshes/wheel4_omniwheel_tyre_v1.stl"/>
      </geometry>
    </collision>
  </link>
  <!-- Joint from wheel4_shaft_holder_v2_3 to wheel4_omniwheel_tyre_v1_54 -->
  <joint name="wheel_4g" type="continuous">
    <origin xyz="-0.0237388 0.0326737 0.0065" rpy="-0.628319 1.5708 0"/>
    <parent link="wheel4_shaft_holder_v2_3"/>
    <child link="wheel4_omniwheel_tyre_v1_54"/>
    <axis xyz="0 0 1"/>
    <limit effort="5" velocity="10"/>
    <joint_properties friction="0.1"/>
  </joint>
  <!-- Link wheel4_omniwheel_tyre_v1_55 -->
  <link name="wheel4_omniwheel_tyre_v1_55">
    <inertial>
      <origin xyz="-6.93633e-10 -2.54402e-18 1.35567e-09" rpy="0 0 0"/>
      <mass value="0.00502735"/>
      <inertia ixx="2.29535e-07" ixy="-7.96359e-25" ixz="8.11134e-13" iyy="2.29535e-07" iyz="2.81419e-30" izz="2.32706e-07"/>
    </inertial>
    <!-- Part wheel4_omniwheel_tyre_v1_55 -->
    <visual>
      <origin xyz="0 -3.46945e-18 0.01625" rpy="1.5708 5.20417e-17 3.46945e-18"/>
      <geometry>
        <mesh filename="package://meshes/wheel4_omniwheel_tyre_v1.stl"/>
      </geometry>
      <material name="wheel4_omniwheel_tyre_v1_55_material">
        <color rgba="0.152941 0.152941 0.152941 1"/>
      </material>
    </visual>
    <collision>
      <origin xyz="0 -3.46945e-18 0.01625" rpy="1.5708 5.20417e-17 3.46945e-18"/>
      <geometry>
        <mesh filename="package://meshes/wheel4_omniwheel_tyre_v1.stl"/>
      </geometry>
    </collision>
  </link>
  <!-- Joint from wheel4_shaft_holder_v2_3 to wheel4_omniwheel_tyre_v1_55 -->
  <joint name="wheel_4f" type="continuous">
    <origin xyz="-0.0384102 0.0124802 0.0065" rpy="-1.5708 1.54666 -0.314159"/>
    <parent link="wheel4_shaft_holder_v2_3"/>
    <child link="wheel4_omniwheel_tyre_v1_55"/>
    <axis xyz="0 0 1"/>
    <limit effort="5" velocity="10"/>
    <joint_properties friction="0.1"/>
  </joint>
  <!-- Link wheel4_omniwheel_tyre_v1_56 -->
  <link name="wheel4_omniwheel_tyre_v1_56">
    <inertial>
      <origin xyz="-6.93633e-10 9.25426e-19 1.35567e-09" rpy="0 0 0"/>
      <mass value="0.00502735"/>
      <inertia ixx="2.29535e-07" ixy="-3.62142e-37" ixz="8.11134e-13" iyy="2.29535e-07" iyz="-1.27417e-23" izz="2.32706e-07"/>
    </inertial>
    <!-- Part wheel4_omniwheel_tyre_v1_56 -->
    <visual>
      <origin xyz="0 0 0.01625" rpy="1.5708 5.20093e-17 -7.88861e-31"/>
      <geometry>
        <mesh filename="package://meshes/wheel4_omniwheel_tyre_v1.stl"/>
      </geometry>
      <material name="wheel4_omniwheel_tyre_v1_56_material">
        <color rgba="0.152941 0.152941 0.152941 1"/>
      </material>
    </visual>
    <collision>
      <origin xyz="0 0 0.01625" rpy="1.5708 5.20093e-17 -7.88861e-31"/>
      <geometry>
        <mesh filename="package://meshes/wheel4_omniwheel_tyre_v1.stl"/>
      </geometry>
    </collision>
  </link>
  <!-- Joint from wheel4_shaft_holder_v2_3 to wheel4_omniwheel_tyre_v1_56 -->
  <joint name="wheel_4e" type="continuous">
    <origin xyz="-0.0384102 -0.0124802 0.0065" rpy="1.25664 1.5708 0"/>
    <parent link="wheel4_shaft_holder_v2_3"/>
    <child link="wheel4_omniwheel_tyre_v1_56"/>
    <axis xyz="0 0 1"/>
    <limit effort="5" velocity="10"/>
    <joint_properties friction="0.1"/>
  </joint>
  <!-- Link wheel4_omniwheel_tyre_v1_57 -->
  <link name="wheel4_omniwheel_tyre_v1_57">
    <inertial>
      <origin xyz="-6.93633e-10 -6.91552e-18 1.35567e-09" rpy="0 0 0"/>
      <mass value="0.00502735"/>
      <inertia ixx="2.29535e-07" ixy="4.5027e-29" ixz="8.11134e-13" iyy="2.29535e-07" iyz="1.76003e-25" izz="2.32706e-07"/>
    </inertial>
    <!-- Part wheel4_omniwheel_tyre_v1_57 -->
    <visual>
      <origin xyz="-1.38778e-17 -6.93889e-18 0.01625" rpy="1.5708 5.20417e-17 -1.73472e-18"/>
      <geometry>
        <mesh filename="package://meshes/wheel4_omniwheel_tyre_v1.stl"/>
      </geometry>
      <material name="wheel4_omniwheel_tyre_v1_57_material">
        <color rgba="0.152941 0.152941 0.152941 1"/>
      </material>
    </visual>
    <collision>
      <origin xyz="-1.38778e-17 -6.93889e-18 0.01625" rpy="1.5708 5.20417e-17 -1.73472e-18"/>
      <geometry>
        <mesh filename="package://meshes/wheel4_omniwheel_tyre_v1.stl"/>
      </geometry>
    </collision>
  </link>
  <!-- Joint from wheel4_shaft_holder_v2_3 to wheel4_omniwheel_tyre_v1_57 -->
  <joint name="wheel_4d" type="continuous">
    <origin xyz="-0.0237388 -0.0326737 0.0065" rpy="-1.5708 1.54071 -2.19911"/>
    <parent link="wheel4_shaft_holder_v2_3"/>
    <child link="wheel4_omniwheel_tyre_v1_57"/>
    <axis xyz="0 0 1"/>
    <limit effort="5" velocity="10"/>
    <joint_properties friction="0.1"/>
  </joint>
  <!-- Link wheel4_omniwheel_tyre_v1_58 -->
  <link name="wheel4_omniwheel_tyre_v1_58">
    <inertial>
      <origin xyz="-6.93633e-10 7.53819e-18 1.35567e-09" rpy="0 0 0"/>
      <mass value="0.00502735"/>
      <inertia ixx="2.29535e-07" ixy="1.62789e-29" ixz="8.11134e-13" iyy="2.29535e-07" iyz="6.3632e-26" izz="2.32706e-07"/>
    </inertial>
    <!-- Part wheel4_omniwheel_tyre_v1_58 -->
    <visual>
      <origin xyz="0 6.93889e-18 0.01625" rpy="1.5708 5.20093e-17 4.06219e-32"/>
      <geometry>
        <mesh filename="package://meshes/wheel4_omniwheel_tyre_v1.stl"/>
      </geometry>
      <material name="wheel4_omniwheel_tyre_v1_58_material">
        <color rgba="0.152941 0.152941 0.152941 1"/>
      </material>
    </visual>
    <collision>
      <origin xyz="0 6.93889e-18 0.01625" rpy="1.5708 5.20093e-17 4.06219e-32"/>
      <geometry>
        <mesh filename="package://meshes/wheel4_omniwheel_tyre_v1.stl"/>
      </geometry>
    </collision>
  </link>
  <!-- Joint from wheel4_shaft_holder_v2_3 to wheel4_omniwheel_tyre_v1_58 -->
  <joint name="wheel_4c" type="continuous">
    <origin xyz="8.67362e-18 -0.0403869 0.0065" rpy="-3.38788e-16 1.5708 0"/>
    <parent link="wheel4_shaft_holder_v2_3"/>
    <child link="wheel4_omniwheel_tyre_v1_58"/>
    <axis xyz="0 0 1"/>
    <limit effort="5" velocity="10"/>
    <joint_properties friction="0.1"/>
  </joint>
  <!-- Link wheel4_omniwheel_tyre_v1_59 -->
  <link name="wheel4_omniwheel_tyre_v1_59">
    <inertial>
      <origin xyz="-6.93633e-10 -6.01347e-18 1.35567e-09" rpy="0 0 0"/>
      <mass value="0.00502735"/>
      <inertia ixx="2.29535e-07" ixy="-1.35803e-37" ixz="8.11134e-13" iyy="2.29535e-07" iyz="-1.27417e-23" izz="2.32706e-07"/>
    </inertial>
    <!-- Part wheel4_omniwheel_tyre_v1_59 -->
    <visual>
      <origin xyz="-1.38778e-17 -6.93889e-18 0.01625" rpy="1.5708 5.20093e-17 -3.9443e-31"/>
      <geometry>
        <mesh filename="package://meshes/wheel4_omniwheel_tyre_v1.stl"/>
      </geometry>
      <material name="wheel4_omniwheel_tyre_v1_59_material">
        <color rgba="0.152941 0.152941 0.152941 1"/>
      </material>
    </visual>
    <collision>
      <origin xyz="-1.38778e-17 -6.93889e-18 0.01625" rpy="1.5708 5.20093e-17 -3.9443e-31"/>
      <geometry>
        <mesh filename="package://meshes/wheel4_omniwheel_tyre_v1.stl"/>
      </geometry>
    </collision>
  </link>
  <!-- Joint from wheel4_shaft_holder_v2_3 to wheel4_omniwheel_tyre_v1_59 -->
  <joint name="wheel_4b" type="continuous">
    <origin xyz="0.0237388 -0.0326737 0.0065" rpy="-0.628319 1.5708 0"/>
    <parent link="wheel4_shaft_holder_v2_3"/>
    <child link="wheel4_omniwheel_tyre_v1_59"/>
    <axis xyz="0 0 1"/>
    <limit effort="5" velocity="10"/>
    <joint_properties friction="0.1"/>
  </joint>
  <!-- Link wheel4_omniwheel_tyre_v1_60 -->
  <link name="wheel4_omniwheel_tyre_v1_60">
    <inertial>
      <origin xyz="-6.93633e-10 -6.01346e-18 1.35567e-09" rpy="0 0 0"/>
      <mass value="0.00502735"/>
      <inertia ixx="2.29535e-07" ixy="8.96137e-23" ixz="8.11134e-13" iyy="2.29535e-07" iyz="1.27378e-23" izz="2.32706e-07"/>
    </inertial>
    <!-- Part wheel4_omniwheel_tyre_v1_60 -->
    <visual>
      <origin xyz="-2.77556e-17 -6.93889e-18 0.01625" rpy="1.5708 5.20093e-17 -4.90091e-15"/>
      <geometry>
        <mesh filename="package://meshes/wheel4_omniwheel_tyre_v1.stl"/>
      </geometry>
      <material name="wheel4_omniwheel_tyre_v1_60_material">
        <color rgba="0.152941 0.152941 0.152941 1"/>
      </material>
    </visual>
    <collision>
      <origin xyz="-2.77556e-17 -6.93889e-18 0.01625" rpy="1.5708 5.20093e-17 -4.90091e-15"/>
      <geometry>
        <mesh filename="package://meshes/wheel4_omniwheel_tyre_v1.stl"/>
      </geometry>
    </collision>
  </link>
  <!-- Joint from wheel4_shaft_holder_v2_3 to wheel4_omniwheel_tyre_v1_60 -->
  <joint name="wheel_4a" type="continuous">
    <origin xyz="0.0384102 -0.0124802 0.0065" rpy="-1.25664 1.5708 0"/>
    <parent link="wheel4_shaft_holder_v2_3"/>
    <child link="wheel4_omniwheel_tyre_v1_60"/>
    <axis xyz="0 0 1"/>
    <limit effort="5" velocity="10"/>
    <joint_properties friction="0.1"/>
  </joint>
  <!-- Joint from part_1 to wheel4_shaft_holder_v2_3 -->
  <joint name="wheel_motorD" type="continuous">
    <origin xyz="-0.105 -1.74334e-17 0.0125" rpy="-1.63015e-15 -1.5708 0"/>
    <parent link="part_1"/>
    <child link="wheel4_shaft_holder_v2_3"/>
    <axis xyz="0 0 1"/>
    <limit effort="5" velocity="10"/>
    <joint_properties friction="0.1"/>
  </joint>
  <!-- Link wheel4_shaft_holder_v2_4 -->
  <link name="wheel4_shaft_holder_v2_4">
    <inertial>
      <origin xyz="3.57043e-13 3.57048e-13 0.0159932" rpy="0 0 0"/>
      <mass value="0.162524"/>
      <inertia ixx="0.000106018" ixy="-1.20702e-20" ixz="-4.58456e-15" iyy="0.000106018" iyz="-5.68704e-15" izz="0.000180425"/>
    </inertial>
    <!-- Part wheel4_shaft_omni_v1_61 -->
    <!-- Part wheel4_shaft_omni_v1_62 -->
    <!-- Part wheel4_shaft_holder_v2_4 -->
    <visual>
      <origin xyz="5.20417e-18 3.61401e-20 0.013" rpy="1.5708 -1.5708 0"/>
      <geometry>
        <mesh filename="package://meshes/wheel4_shaft_holder_v2.stl"/>
      </geometry>
      <material name="wheel4_shaft_holder_v2_4_material">
        <color rgba="0.627451 0.627451 0.627451 1"/>
      </material>
    </visual>
    <!-- Part wheel4_shaft_omni_v1_63 -->
    <!-- Part wheel4_shaft_omni_v1_64 -->
    <!-- Part wheel4_shaft_omni_v1_65 -->
    <!-- Part wheel4_shaft_omni_v1_66 -->
    <!-- Part wheel4_shaft_omni_v1_67 -->
    <!-- Part wheel4_shaft_omni_v1_68 -->
    <!-- Part wheel4_body_omni_v4_7 -->
    <visual>
      <origin xyz="0 0 0.013" rpy="1.5708 1.5708 0"/>
      <geometry>
        <mesh filename="package://meshes/wheel4_body_omni_v4__2.stl"/>
      </geometry>
      <material name="wheel4_body_omni_v4_7_material">
        <color rgba="0.627451 0.627451 0.627451 1"/>
      </material>
    </visual>
    <!-- Part wheel4_shaft_omni_v1_69 -->
    <!-- Part wheel4_shaft_omni_v1_70 -->
    <!-- Part wheel4_shaft_omni_v1_71 -->
    <!-- Part wheel4_shaft_omni_v1_72 -->
    <!-- Part wheel4_shaft_omni_v1_73 -->
    <!-- Part wheel4_shaft_omni_v1_74 -->
    <!-- Part wheel4_body_omni_v4_8 -->
    <visual>
      <origin xyz="-2.94903e-17 1.9877e-18 0.032" rpy="-6.77576e-16 1.5708 0"/>
      <geometry>
        <mesh filename="package://meshes/wheel4_body_omni_v4.stl"/>
      </geometry>
      <material name="wheel4_body_omni_v4_8_material">
        <color rgba="0.627451 0.627451 0.627451 1"/>
      </material>
    </visual>
    <!-- Part wheel4_shaft_omni_v1_75 -->
    <!-- Part wheel4_shaft_omni_v1_76 -->
    <!-- Part wheel4_shaft_omni_v1_77 -->
    <!-- Part wheel4_shaft_omni_v1_78 -->
    <!-- Part wheel4_shaft_omni_v1_79 -->
    <!-- Part wheel4_shaft_omni_v1_80 -->
  </link>
  <!-- Frame motorB (dummy link + fixed joint) -->
  <link name="motorB">
    <origin xyz="0 0 0" rpy="0 -0 0"/>
    <inertial>
      <origin xyz="0 0 0" rpy="0 0 0"/>
      <mass value="1e-9"/>
      <inertia ixx="0" ixy="0" ixz="0" iyy="0" iyz="0" izz="0"/>
    </inertial>
  </link>
  <joint name="motorB_frame" type="fixed">
    <origin xyz="-1.73472e-18 3.37024e-19 0" rpy="3.14159 -5.60071e-60 -1.5708"/>
    <parent link="wheel4_shaft_holder_v2_4"/>
    <child link="motorB"/>
    <axis xyz="0 0 0"/>
  </joint>
  <!-- Link wheel4_omniwheel_tyre_v1_61 -->
  <link name="wheel4_omniwheel_tyre_v1_61">
    <inertial>
      <origin xyz="-6.93633e-10 1.44771e-17 1.35567e-09" rpy="0 0 0"/>
      <mass value="0.00502735"/>
      <inertia ixx="2.29535e-07" ixy="2.54835e-23" ixz="8.11134e-13" iyy="2.29535e-07" iyz="6.3677e-26" izz="2.32706e-07"/>
    </inertial>
    <!-- Part wheel4_omniwheel_tyre_v1_61 -->
    <visual>
      <origin xyz="1.38778e-17 1.38778e-17 0.01625" rpy="1.5708 5.20093e-17 5.55112e-17"/>
      <geometry>
        <mesh filename="package://meshes/wheel4_omniwheel_tyre_v1.stl"/>
      </geometry>
      <material name="wheel4_omniwheel_tyre_v1_61_material">
        <color rgba="0.152941 0.152941 0.152941 1"/>
      </material>
    </visual>
    <collision>
      <origin xyz="1.38778e-17 1.38778e-17 0.01625" rpy="1.5708 5.20093e-17 5.55112e-17"/>
      <geometry>
        <mesh filename="package://meshes/wheel4_omniwheel_tyre_v1.stl"/>
      </geometry>
    </collision>
  </link>
  <!-- Joint from wheel4_shaft_holder_v2_4 to wheel4_omniwheel_tyre_v1_61 -->
  <joint name="wheel_2k" type="continuous">
    <origin xyz="-0.0403869 -2.71773e-17 0.0255" rpy="1.5708 0.992087 3.14159"/>
    <parent link="wheel4_shaft_holder_v2_4"/>
    <child link="wheel4_omniwheel_tyre_v1_61"/>
    <axis xyz="0 0 1"/>
    <limit effort="5" velocity="10"/>
    <joint_properties friction="0.1"/>
  </joint>
  <!-- Link wheel4_omniwheel_tyre_v1_62 -->
  <link name="wheel4_omniwheel_tyre_v1_62">
    <inertial>
      <origin xyz="-6.93633e-10 6.96226e-18 1.35567e-09" rpy="0 0 0"/>
      <mass value="0.00502735"/>
      <inertia ixx="2.29535e-07" ixy="4.5027e-29" ixz="8.11134e-13" iyy="2.29535e-07" iyz="2.56595e-23" izz="2.32706e-07"/>
    </inertial>
    <!-- Part wheel4_omniwheel_tyre_v1_62 -->
    <visual>
      <origin xyz="0 6.93889e-18 0.01625" rpy="1.5708 5.20093e-17 0"/>
      <geometry>
        <mesh filename="package://meshes/wheel4_omniwheel_tyre_v1.stl"/>
      </geometry>
      <material name="wheel4_omniwheel_tyre_v1_62_material">
        <color rgba="0.152941 0.152941 0.152941 1"/>
      </material>
    </visual>
    <collision>
      <origin xyz="0 6.93889e-18 0.01625" rpy="1.5708 5.20093e-17 0"/>
      <geometry>
        <mesh filename="package://meshes/wheel4_omniwheel_tyre_v1.stl"/>
      </geometry>
    </collision>
  </link>
  <!-- Joint from wheel4_shaft_holder_v2_4 to wheel4_omniwheel_tyre_v1_62 -->
  <joint name="wheel_2l" type="continuous">
    <origin xyz="-0.0326737 0.0237388 0.0255" rpy="-2.19911 -1.5708 0"/>
    <parent link="wheel4_shaft_holder_v2_4"/>
    <child link="wheel4_omniwheel_tyre_v1_62"/>
    <axis xyz="0 0 1"/>
    <limit effort="5" velocity="10"/>
    <joint_properties friction="0.1"/>
  </joint>
  <!-- Link wheel4_omniwheel_tyre_v1_63 -->
  <link name="wheel4_omniwheel_tyre_v1_63">
    <inertial>
      <origin xyz="-6.93633e-10 9.25426e-19 1.35567e-09" rpy="0 0 0"/>
      <mass value="0.00502735"/>
      <inertia ixx="2.29535e-07" ixy="4.52678e-38" ixz="8.11134e-13" iyy="2.29535e-07" iyz="-1.59968e-43" izz="2.32706e-07"/>
    </inertial>
    <!-- Part wheel4_omniwheel_tyre_v1_63 -->
    <visual>
      <origin xyz="2.77556e-17 0 0.01625" rpy="1.5708 5.20093e-17 -1.97215e-31"/>
      <geometry>
        <mesh filename="package://meshes/wheel4_omniwheel_tyre_v1.stl"/>
      </geometry>
      <material name="wheel4_omniwheel_tyre_v1_63_material">
        <color rgba="0.152941 0.152941 0.152941 1"/>
      </material>
    </visual>
    <collision>
      <origin xyz="2.77556e-17 0 0.01625" rpy="1.5708 5.20093e-17 -1.97215e-31"/>
      <geometry>
        <mesh filename="package://meshes/wheel4_omniwheel_tyre_v1.stl"/>
      </geometry>
    </collision>
  </link>
  <!-- Joint from wheel4_shaft_holder_v2_4 to wheel4_omniwheel_tyre_v1_63 -->
  <joint name="wheel_2m" type="continuous">
    <origin xyz="-0.0124802 0.0384102 0.0255" rpy="-2.82743 -1.5708 0"/>
    <parent link="wheel4_shaft_holder_v2_4"/>
    <child link="wheel4_omniwheel_tyre_v1_63"/>
    <axis xyz="0 0 1"/>
    <limit effort="5" velocity="10"/>
    <joint_properties friction="0.1"/>
  </joint>
  <!-- Link wheel4_omniwheel_tyre_v1_64 -->
  <link name="wheel4_omniwheel_tyre_v1_64">
    <inertial>
      <origin xyz="-6.93633e-10 7.86432e-18 1.35567e-09" rpy="0 0 0"/>
      <mass value="0.00502735"/>
      <inertia ixx="2.29535e-07" ixy="2.26339e-38" ixz="8.11134e-13" iyy="2.29535e-07" iyz="7.9984e-44" izz="2.32706e-07"/>
    </inertial>
    <!-- Part wheel4_omniwheel_tyre_v1_64 -->
    <visual>
      <origin xyz="0 6.93889e-18 0.01625" rpy="1.5708 5.20093e-17 9.86076e-32"/>
      <geometry>
        <mesh filename="package://meshes/wheel4_omniwheel_tyre_v1.stl"/>
      </geometry>
      <material name="wheel4_omniwheel_tyre_v1_64_material">
        <color rgba="0.152941 0.152941 0.152941 1"/>
      </material>
    </visual>
    <collision>
      <origin xyz="0 6.93889e-18 0.01625" rpy="1.5708 5.20093e-17 9.86076e-32"/>
      <geometry>
        <mesh filename="package://meshes/wheel4_omniwheel_tyre_v1.stl"/>
      </geometry>
    </collision>
  </link>
  <!-- Joint from wheel4_shaft_holder_v2_4 to wheel4_omniwheel_tyre_v1_64 -->
  <joint name="wheel_2n" type="continuous">
    <origin xyz="0.0124802 0.0384102 0.0255" rpy="-0.314159 -1.5708 0"/>
    <parent link="wheel4_shaft_holder_v2_4"/>
    <child link="wheel4_omniwheel_tyre_v1_64"/>
    <axis xyz="0 0 1"/>
    <limit effort="5" velocity="10"/>
    <joint_properties friction="0.1"/>
  </joint>
  <!-- Link wheel4_omniwheel_tyre_v1_65 -->
  <link name="wheel4_omniwheel_tyre_v1_65">
    <inertial>
      <origin xyz="-6.93633e-10 1.48032e-17 1.35567e-09" rpy="0 0 0"/>
      <mass value="0.00502735"/>
      <inertia ixx="2.29535e-07" ixy="1.67986e-38" ixz="8.11134e-13" iyy="2.29535e-07" iyz="1.27417e-23" izz="2.32706e-07"/>
    </inertial>
    <!-- Part wheel4_omniwheel_tyre_v1_65 -->
    <visual>
      <origin xyz="0 1.38778e-17 0.01625" rpy="1.5708 5.20093e-17 5.46964e-32"/>
      <geometry>
        <mesh filename="package://meshes/wheel4_omniwheel_tyre_v1.stl"/>
      </geometry>
      <material name="wheel4_omniwheel_tyre_v1_65_material">
        <color rgba="0.152941 0.152941 0.152941 1"/>
      </material>
    </visual>
    <collision>
      <origin xyz="0 1.38778e-17 0.01625" rpy="1.5708 5.20093e-17 5.46964e-32"/>
      <geometry>
        <mesh filename="package://meshes/wheel4_omniwheel_tyre_v1.stl"/>
      </geometry>
    </collision>
  </link>
  <!-- Joint from wheel4_shaft_holder_v2_4 to wheel4_omniwheel_tyre_v1_65 -->
  <joint name="wheel_2o" type="continuous">
    <origin xyz="0.0326737 0.0237388 0.0255" rpy="-0.942478 -1.5708 0"/>
    <parent link="wheel4_shaft_holder_v2_4"/>
    <child link="wheel4_omniwheel_tyre_v1_65"/>
    <axis xyz="0 0 1"/>
    <limit effort="5" velocity="10"/>
    <joint_properties friction="0.1"/>
  </joint>
  <!-- Link wheel4_omniwheel_tyre_v1_66 -->
  <link name="wheel4_omniwheel_tyre_v1_66">
    <inertial>
      <origin xyz="-6.93633e-10 5.993e-19 1.35567e-09" rpy="0 0 0"/>
      <mass value="0.00502735"/>
      <inertia ixx="2.29535e-07" ixy="2.54835e-23" ixz="8.11134e-13" iyy="2.29535e-07" iyz="6.3677e-26" izz="2.32706e-07"/>
    </inertial>
    <!-- Part wheel4_omniwheel_tyre_v1_66 -->
    <visual>
      <origin xyz="0 0 0.01625" rpy="1.5708 5.20093e-17 5.55112e-17"/>
      <geometry>
        <mesh filename="package://meshes/wheel4_omniwheel_tyre_v1.stl"/>
      </geometry>
      <material name="wheel4_omniwheel_tyre_v1_66_material">
        <color rgba="0.152941 0.152941 0.152941 1"/>
      </material>
    </visual>
    <collision>
      <origin xyz="0 0 0.01625" rpy="1.5708 5.20093e-17 5.55112e-17"/>
      <geometry>
        <mesh filename="package://meshes/wheel4_omniwheel_tyre_v1.stl"/>
      </geometry>
    </collision>
  </link>
  <!-- Joint from wheel4_shaft_holder_v2_4 to wheel4_omniwheel_tyre_v1_66 -->
  <joint name="wheel_2p" type="continuous">
    <origin xyz="0.0403869 2.83338e-17 0.0255" rpy="1.5708 0.992087 3.14159"/>
    <parent link="wheel4_shaft_holder_v2_4"/>
    <child link="wheel4_omniwheel_tyre_v1_66"/>
    <axis xyz="0 0 1"/>
    <limit effort="5" velocity="10"/>
    <joint_properties friction="0.1"/>
  </joint>
  <!-- Link wheel4_omniwheel_tyre_v1_67 -->
  <link name="wheel4_omniwheel_tyre_v1_67">
    <inertial>
      <origin xyz="-6.93633e-10 6.96226e-18 1.35567e-09" rpy="0 0 0"/>
      <mass value="0.00502735"/>
      <inertia ixx="2.29535e-07" ixy="4.5027e-29" ixz="8.11134e-13" iyy="2.29535e-07" iyz="2.56595e-23" izz="2.32706e-07"/>
    </inertial>
    <!-- Part wheel4_omniwheel_tyre_v1_67 -->
    <visual>
      <origin xyz="0 6.93889e-18 0.01625" rpy="1.5708 5.20093e-17 -1.57772e-30"/>
      <geometry>
        <mesh filename="package://meshes/wheel4_omniwheel_tyre_v1.stl"/>
      </geometry>
      <material name="wheel4_omniwheel_tyre_v1_67_material">
        <color rgba="0.152941 0.152941 0.152941 1"/>
      </material>
    </visual>
    <collision>
      <origin xyz="0 6.93889e-18 0.01625" rpy="1.5708 5.20093e-17 -1.57772e-30"/>
      <geometry>
        <mesh filename="package://meshes/wheel4_omniwheel_tyre_v1.stl"/>
      </geometry>
    </collision>
  </link>
  <!-- Joint from wheel4_shaft_holder_v2_4 to wheel4_omniwheel_tyre_v1_67 -->
  <joint name="wheel_2q" type="continuous">
    <origin xyz="0.0326737 -0.0237388 0.0255" rpy="-2.19911 -1.5708 0"/>
    <parent link="wheel4_shaft_holder_v2_4"/>
    <child link="wheel4_omniwheel_tyre_v1_67"/>
    <axis xyz="0 0 1"/>
    <limit effort="5" velocity="10"/>
    <joint_properties friction="0.1"/>
  </joint>
  <!-- Link wheel4_omniwheel_tyre_v1_68 -->
  <link name="wheel4_omniwheel_tyre_v1_68">
    <inertial>
      <origin xyz="-6.93633e-10 1.34501e-17 1.35567e-09" rpy="0 0 0"/>
      <mass value="0.00502735"/>
      <inertia ixx="2.29535e-07" ixy="2.38908e-23" ixz="8.11134e-13" iyy="2.29535e-07" iyz="2.57476e-23" izz="2.32706e-07"/>
    </inertial>
    <!-- Part wheel4_omniwheel_tyre_v1_68 -->
    <visual>
      <origin xyz="-1.38778e-17 1.38778e-17 0.01625" rpy="1.5708 5.55112e-17 7.63278e-17"/>
      <geometry>
        <mesh filename="package://meshes/wheel4_omniwheel_tyre_v1.stl"/>
      </geometry>
      <material name="wheel4_omniwheel_tyre_v1_68_material">
        <color rgba="0.152941 0.152941 0.152941 1"/>
      </material>
    </visual>
    <collision>
      <origin xyz="-1.38778e-17 1.38778e-17 0.01625" rpy="1.5708 5.55112e-17 7.63278e-17"/>
      <geometry>
        <mesh filename="package://meshes/wheel4_omniwheel_tyre_v1.stl"/>
      </geometry>
    </collision>
  </link>
  <!-- Joint from wheel4_shaft_holder_v2_4 to wheel4_omniwheel_tyre_v1_68 -->
  <joint name="wheel_2r" type="continuous">
    <origin xyz="0.0124802 -0.0384102 0.0255" rpy="1.5708 -1.00644 1.88496"/>
    <parent link="wheel4_shaft_holder_v2_4"/>
    <child link="wheel4_omniwheel_tyre_v1_68"/>
    <axis xyz="0 0 1"/>
    <limit effort="5" velocity="10"/>
    <joint_properties friction="0.1"/>
  </joint>
  <!-- Link wheel4_omniwheel_tyre_v1_69 -->
  <link name="wheel4_omniwheel_tyre_v1_69">
    <inertial>
      <origin xyz="-6.93633e-10 9.25426e-19 1.35567e-09" rpy="0 0 0"/>
      <mass value="0.00502735"/>
      <inertia ixx="2.29535e-07" ixy="4.52678e-38" ixz="8.11134e-13" iyy="2.29535e-07" iyz="1.27417e-23" izz="2.32706e-07"/>
    </inertial>
    <!-- Part wheel4_omniwheel_tyre_v1_69 -->
    <visual>
      <origin xyz="0 0 0.01625" rpy="1.5708 5.20093e-17 9.86076e-32"/>
      <geometry>
        <mesh filename="package://meshes/wheel4_omniwheel_tyre_v1.stl"/>
      </geometry>
      <material name="wheel4_omniwheel_tyre_v1_69_material">
        <color rgba="0.152941 0.152941 0.152941 1"/>
      </material>
    </visual>
    <collision>
      <origin xyz="0 0 0.01625" rpy="1.5708 5.20093e-17 9.86076e-32"/>
      <geometry>
        <mesh filename="package://meshes/wheel4_omniwheel_tyre_v1.stl"/>
      </geometry>
    </collision>
  </link>
  <!-- Joint from wheel4_shaft_holder_v2_4 to wheel4_omniwheel_tyre_v1_69 -->
  <joint name="wheel_2s" type="continuous">
    <origin xyz="-0.0124802 -0.0384102 0.0255" rpy="-0.314159 -1.5708 0"/>
    <parent link="wheel4_shaft_holder_v2_4"/>
    <child link="wheel4_omniwheel_tyre_v1_69"/>
    <axis xyz="0 0 1"/>
    <limit effort="5" velocity="10"/>
    <joint_properties friction="0.1"/>
  </joint>
  <!-- Link wheel4_omniwheel_tyre_v1_70 -->
  <link name="wheel4_omniwheel_tyre_v1_70">
    <inertial>
      <origin xyz="-6.93633e-10 -6.01347e-18 1.35567e-09" rpy="0 0 0"/>
      <mass value="0.00502735"/>
      <inertia ixx="2.29535e-07" ixy="-3.39508e-38" ixz="8.11134e-13" iyy="2.29535e-07" iyz="-7.9984e-44" izz="2.32706e-07"/>
    </inertial>
    <!-- Part wheel4_omniwheel_tyre_v1_70 -->
    <visual>
      <origin xyz="0 -6.93889e-18 0.01625" rpy="1.5708 5.20093e-17 -9.86076e-32"/>
      <geometry>
        <mesh filename="package://meshes/wheel4_omniwheel_tyre_v1.stl"/>
      </geometry>
      <material name="wheel4_omniwheel_tyre_v1_70_material">
        <color rgba="0.152941 0.152941 0.152941 1"/>
      </material>
    </visual>
    <collision>
      <origin xyz="0 -6.93889e-18 0.01625" rpy="1.5708 5.20093e-17 -9.86076e-32"/>
      <geometry>
        <mesh filename="package://meshes/wheel4_omniwheel_tyre_v1.stl"/>
      </geometry>
    </collision>
  </link>
  <!-- Joint from wheel4_shaft_holder_v2_4 to wheel4_omniwheel_tyre_v1_70 -->
  <joint name="wheel_2t" type="continuous">
    <origin xyz="-0.0326737 -0.0237388 0.0255" rpy="-0.942478 -1.5708 0"/>
    <parent link="wheel4_shaft_holder_v2_4"/>
    <child link="wheel4_omniwheel_tyre_v1_70"/>
    <axis xyz="0 0 1"/>
    <limit effort="5" velocity="10"/>
    <joint_properties friction="0.1"/>
  </joint>
  <!-- Link wheel4_omniwheel_tyre_v1_71 -->
  <link name="wheel4_omniwheel_tyre_v1_71">
    <inertial>
      <origin xyz="-6.93633e-10 -2.33695e-20 -1.46309e-09" rpy="0 0 0"/>
      <mass value="0.00502735"/>
      <inertia ixx="2.29535e-07" ixy="-4.5027e-29" ixz="-8.11134e-13" iyy="2.29535e-07" iyz="1.29178e-23" izz="2.32706e-07"/>
    </inertial>
    <!-- Part wheel4_omniwheel_tyre_v1_71 -->
    <visual>
      <origin xyz="0 0 -0.01625" rpy="-1.5708 -0 0"/>
      <geometry>
        <mesh filename="package://meshes/wheel4_omniwheel_tyre_v1.stl"/>
      </geometry>
      <material name="wheel4_omniwheel_tyre_v1_71_material">
        <color rgba="0.152941 0.152941 0.152941 1"/>
      </material>
    </visual>
    <collision>
      <origin xyz="0 0 -0.01625" rpy="-1.5708 -0 0"/>
      <geometry>
        <mesh filename="package://meshes/wheel4_omniwheel_tyre_v1.stl"/>
      </geometry>
    </collision>
  </link>
  <!-- Joint from wheel4_shaft_holder_v2_4 to wheel4_omniwheel_tyre_v1_71 -->
  <joint name="wheel_2j" type="continuous">
    <origin xyz="0.0384102 0.0124802 0.0065" rpy="-1.25664 -1.5708 0"/>
    <parent link="wheel4_shaft_holder_v2_4"/>
    <child link="wheel4_omniwheel_tyre_v1_71"/>
    <axis xyz="0 0 1"/>
    <limit effort="5" velocity="10"/>
    <joint_properties friction="0.1"/>
  </joint>
  <!-- Link wheel4_omniwheel_tyre_v1_72 -->
  <link name="wheel4_omniwheel_tyre_v1_72">
    <inertial>
      <origin xyz="-6.93633e-10 6.06021e-18 1.35567e-09" rpy="0 0 0"/>
      <mass value="0.00502735"/>
      <inertia ixx="2.29535e-07" ixy="9.00539e-29" ixz="8.11134e-13" iyy="2.29535e-07" iyz="2.58355e-23" izz="2.32706e-07"/>
    </inertial>
    <!-- Part wheel4_omniwheel_tyre_v1_72 -->
    <visual>
      <origin xyz="1.38778e-17 6.93889e-18 0.01625" rpy="1.5708 5.20093e-17 1.97215e-31"/>
      <geometry>
        <mesh filename="package://meshes/wheel4_omniwheel_tyre_v1.stl"/>
      </geometry>
      <material name="wheel4_omniwheel_tyre_v1_72_material">
        <color rgba="0.152941 0.152941 0.152941 1"/>
      </material>
    </visual>
    <collision>
      <origin xyz="1.38778e-17 6.93889e-18 0.01625" rpy="1.5708 5.20093e-17 1.97215e-31"/>
      <geometry>
        <mesh filename="package://meshes/wheel4_omniwheel_tyre_v1.stl"/>
      </geometry>
    </collision>
  </link>
  <!-- Joint from wheel4_shaft_holder_v2_4 to wheel4_omniwheel_tyre_v1_72 -->
  <joint name="wheel_2i" type="continuous">
    <origin xyz="0.0237388 0.0326737 0.0065" rpy="2.51327 -1.5708 0"/>
    <parent link="wheel4_shaft_holder_v2_4"/>
    <child link="wheel4_omniwheel_tyre_v1_72"/>
    <axis xyz="0 0 1"/>
    <limit effort="5" velocity="10"/>
    <joint_properties friction="0.1"/>
  </joint>
  <!-- Link wheel4_omniwheel_tyre_v1_73 -->
  <link name="wheel4_omniwheel_tyre_v1_73">
    <inertial>
      <origin xyz="6.93633e-10 -5.99301e-19 1.35567e-09" rpy="0 0 0"/>
      <mass value="0.00502735"/>
      <inertia ixx="2.29535e-07" ixy="1.62789e-29" ixz="-8.11134e-13" iyy="2.29535e-07" iyz="-6.32193e-26" izz="2.32706e-07"/>
    </inertial>
    <!-- Part wheel4_omniwheel_tyre_v1_73 -->
    <visual>
      <origin xyz="-2.77556e-17 0 0.01625" rpy="1.5708 5.20093e-17 3.14159"/>
      <geometry>
        <mesh filename="package://meshes/wheel4_omniwheel_tyre_v1.stl"/>
      </geometry>
      <material name="wheel4_omniwheel_tyre_v1_73_material">
        <color rgba="0.152941 0.152941 0.152941 1"/>
      </material>
    </visual>
    <collision>
      <origin xyz="-2.77556e-17 0 0.01625" rpy="1.5708 5.20093e-17 3.14159"/>
      <geometry>
        <mesh filename="package://meshes/wheel4_omniwheel_tyre_v1.stl"/>
      </geometry>
    </collision>
  </link>
  <!-- Joint from wheel4_shaft_holder_v2_4 to wheel4_omniwheel_tyre_v1_73 -->
  <joint name="wheel_2h" type="continuous">
    <origin xyz="1.73472e-18 0.0403869 0.0065" rpy="-4.44089e-16 1.5708 0"/>
    <parent link="wheel4_shaft_holder_v2_4"/>
    <child link="wheel4_omniwheel_tyre_v1_73"/>
    <axis xyz="0 0 1"/>
    <limit effort="5" velocity="10"/>
    <joint_properties friction="0.1"/>
  </joint>
  <!-- Link wheel4_omniwheel_tyre_v1_74 -->
  <link name="wheel4_omniwheel_tyre_v1_74">
    <inertial>
      <origin xyz="-6.93633e-10 8.76638e-18 1.35567e-09" rpy="0 0 0"/>
      <mass value="0.00502735"/>
      <inertia ixx="2.29535e-07" ixy="-4.5027e-29" ixz="8.11134e-13" iyy="2.29535e-07" iyz="-1.76005e-25" izz="2.32706e-07"/>
    </inertial>
    <!-- Part wheel4_omniwheel_tyre_v1_74 -->
    <visual>
      <origin xyz="0 6.93889e-18 0.01625" rpy="1.5708 5.20093e-17 -4.93038e-32"/>
      <geometry>
        <mesh filename="package://meshes/wheel4_omniwheel_tyre_v1.stl"/>
      </geometry>
      <material name="wheel4_omniwheel_tyre_v1_74_material">
        <color rgba="0.152941 0.152941 0.152941 1"/>
      </material>
    </visual>
    <collision>
      <origin xyz="0 6.93889e-18 0.01625" rpy="1.5708 5.20093e-17 -4.93038e-32"/>
      <geometry>
        <mesh filename="package://meshes/wheel4_omniwheel_tyre_v1.stl"/>
      </geometry>
    </collision>
  </link>
  <!-- Joint from wheel4_shaft_holder_v2_4 to wheel4_omniwheel_tyre_v1_74 -->
  <joint name="wheel_2g" type="continuous">
    <origin xyz="-0.0237388 0.0326737 0.0065" rpy="-2.51327 -1.5708 0"/>
    <parent link="wheel4_shaft_holder_v2_4"/>
    <child link="wheel4_omniwheel_tyre_v1_74"/>
    <axis xyz="0 0 1"/>
    <limit effort="5" velocity="10"/>
    <joint_properties friction="0.1"/>
  </joint>
  <!-- Link wheel4_omniwheel_tyre_v1_75 -->
  <link name="wheel4_omniwheel_tyre_v1_75">
    <inertial>
      <origin xyz="-6.93633e-10 -2.54402e-18 1.35567e-09" rpy="0 0 0"/>
      <mass value="0.00502735"/>
      <inertia ixx="2.29535e-07" ixy="7.96359e-25" ixz="8.11134e-13" iyy="2.29535e-07" iyz="-1.27417e-23" izz="2.32706e-07"/>
    </inertial>
    <!-- Part wheel4_omniwheel_tyre_v1_75 -->
    <visual>
      <origin xyz="1.38778e-17 -3.46945e-18 0.01625" rpy="1.5708 5.11743e-17 0"/>
      <geometry>
        <mesh filename="package://meshes/wheel4_omniwheel_tyre_v1.stl"/>
      </geometry>
      <material name="wheel4_omniwheel_tyre_v1_75_material">
        <color rgba="0.152941 0.152941 0.152941 1"/>
      </material>
    </visual>
    <collision>
      <origin xyz="1.38778e-17 -3.46945e-18 0.01625" rpy="1.5708 5.11743e-17 0"/>
      <geometry>
        <mesh filename="package://meshes/wheel4_omniwheel_tyre_v1.stl"/>
      </geometry>
    </collision>
  </link>
  <!-- Joint from wheel4_shaft_holder_v2_4 to wheel4_omniwheel_tyre_v1_75 -->
  <joint name="wheel_2f" type="continuous">
    <origin xyz="-0.0384102 0.0124802 0.0065" rpy="1.5708 -1.54666 2.82743"/>
    <parent link="wheel4_shaft_holder_v2_4"/>
    <child link="wheel4_omniwheel_tyre_v1_75"/>
    <axis xyz="0 0 1"/>
    <limit effort="5" velocity="10"/>
    <joint_properties friction="0.1"/>
  </joint>
  <!-- Link wheel4_omniwheel_tyre_v1_76 -->
  <link name="wheel4_omniwheel_tyre_v1_76">
    <inertial>
      <origin xyz="-6.93633e-10 9.25426e-19 1.35567e-09" rpy="0 0 0"/>
      <mass value="0.00502735"/>
      <inertia ixx="2.29535e-07" ixy="0" ixz="8.11134e-13" iyy="2.29535e-07" iyz="0" izz="2.32706e-07"/>
    </inertial>
    <!-- Part wheel4_omniwheel_tyre_v1_76 -->
    <visual>
      <origin xyz="0 0 0.01625" rpy="1.5708 5.20093e-17 0"/>
      <geometry>
        <mesh filename="package://meshes/wheel4_omniwheel_tyre_v1.stl"/>
      </geometry>
      <material name="wheel4_omniwheel_tyre_v1_76_material">
        <color rgba="0.152941 0.152941 0.152941 1"/>
      </material>
    </visual>
    <collision>
      <origin xyz="0 0 0.01625" rpy="1.5708 5.20093e-17 0"/>
      <geometry>
        <mesh filename="package://meshes/wheel4_omniwheel_tyre_v1.stl"/>
      </geometry>
    </collision>
  </link>
  <!-- Joint from wheel4_shaft_holder_v2_4 to wheel4_omniwheel_tyre_v1_76 -->
  <joint name="wheel_2e" type="continuous">
    <origin xyz="-0.0384102 -0.0124802 0.0065" rpy="1.88496 -1.5708 0"/>
    <parent link="wheel4_shaft_holder_v2_4"/>
    <child link="wheel4_omniwheel_tyre_v1_76"/>
    <axis xyz="0 0 1"/>
    <limit effort="5" velocity="10"/>
    <joint_properties friction="0.1"/>
  </joint>
  <!-- Link wheel4_omniwheel_tyre_v1_77 -->
  <link name="wheel4_omniwheel_tyre_v1_77">
    <inertial>
      <origin xyz="-6.93633e-10 6.06021e-18 1.35567e-09" rpy="0 0 0"/>
      <mass value="0.00502735"/>
      <inertia ixx="2.29535e-07" ixy="-1.99081e-24" ixz="8.11134e-13" iyy="2.29535e-07" iyz="1.30938e-23" izz="2.32706e-07"/>
    </inertial>
    <!-- Part wheel4_omniwheel_tyre_v1_77 -->
    <visual>
      <origin xyz="1.38778e-17 6.93889e-18 0.01625" rpy="1.5708 5.37764e-17 -5.20417e-18"/>
      <geometry>
        <mesh filename="package://meshes/wheel4_omniwheel_tyre_v1.stl"/>
      </geometry>
      <material name="wheel4_omniwheel_tyre_v1_77_material">
        <color rgba="0.152941 0.152941 0.152941 1"/>
      </material>
    </visual>
    <collision>
      <origin xyz="1.38778e-17 6.93889e-18 0.01625" rpy="1.5708 5.37764e-17 -5.20417e-18"/>
      <geometry>
        <mesh filename="package://meshes/wheel4_omniwheel_tyre_v1.stl"/>
      </geometry>
    </collision>
  </link>
  <!-- Joint from wheel4_shaft_holder_v2_4 to wheel4_omniwheel_tyre_v1_77 -->
  <joint name="wheel_2d" type="continuous">
    <origin xyz="-0.0237388 -0.0326737 0.0065" rpy="1.5708 -1.54071 0.942478"/>
    <parent link="wheel4_shaft_holder_v2_4"/>
    <child link="wheel4_omniwheel_tyre_v1_77"/>
    <axis xyz="0 0 1"/>
    <limit effort="5" velocity="10"/>
    <joint_properties friction="0.1"/>
  </joint>
  <!-- Link wheel4_omniwheel_tyre_v1_78 -->
  <link name="wheel4_omniwheel_tyre_v1_78">
    <inertial>
      <origin xyz="-6.93633e-10 -6.33959e-18 1.35567e-09" rpy="0 0 0"/>
      <mass value="0.00502735"/>
      <inertia ixx="2.29535e-07" ixy="1.62789e-29" ixz="8.11134e-13" iyy="2.29535e-07" iyz="6.3632e-26" izz="2.32706e-07"/>
    </inertial>
    <!-- Part wheel4_omniwheel_tyre_v1_78 -->
    <visual>
      <origin xyz="0 -6.93889e-18 0.01625" rpy="1.5708 5.20093e-17 5.38162e-33"/>
      <geometry>
        <mesh filename="package://meshes/wheel4_omniwheel_tyre_v1.stl"/>
      </geometry>
      <material name="wheel4_omniwheel_tyre_v1_78_material">
        <color rgba="0.152941 0.152941 0.152941 1"/>
      </material>
    </visual>
    <collision>
      <origin xyz="0 -6.93889e-18 0.01625" rpy="1.5708 5.20093e-17 5.38162e-33"/>
      <geometry>
        <mesh filename="package://meshes/wheel4_omniwheel_tyre_v1.stl"/>
      </geometry>
    </collision>
  </link>
  <!-- Joint from wheel4_shaft_holder_v2_4 to wheel4_omniwheel_tyre_v1_78 -->
  <joint name="wheel_2c" type="continuous">
    <origin xyz="1.21431e-17 -0.0403869 0.0065" rpy="-3.14159 -1.5708 0"/>
    <parent link="wheel4_shaft_holder_v2_4"/>
    <child link="wheel4_omniwheel_tyre_v1_78"/>
    <axis xyz="0 0 1"/>
    <limit effort="5" velocity="10"/>
    <joint_properties friction="0.1"/>
  </joint>
  <!-- Link wheel4_omniwheel_tyre_v1_79 -->
  <link name="wheel4_omniwheel_tyre_v1_79">
    <inertial>
      <origin xyz="-6.93633e-10 -6.91552e-18 1.35567e-09" rpy="0 0 0"/>
      <mass value="0.00502735"/>
      <inertia ixx="2.29535e-07" ixy="4.5027e-29" ixz="8.11134e-13" iyy="2.29535e-07" iyz="1.29178e-23" izz="2.32706e-07"/>
    </inertial>
    <!-- Part wheel4_omniwheel_tyre_v1_79 -->
    <visual>
      <origin xyz="0 -6.93889e-18 0.01625" rpy="1.5708 5.20093e-17 9.86076e-32"/>
      <geometry>
        <mesh filename="package://meshes/wheel4_omniwheel_tyre_v1.stl"/>
      </geometry>
      <material name="wheel4_omniwheel_tyre_v1_79_material">
        <color rgba="0.152941 0.152941 0.152941 1"/>
      </material>
    </visual>
    <collision>
      <origin xyz="0 -6.93889e-18 0.01625" rpy="1.5708 5.20093e-17 9.86076e-32"/>
      <geometry>
        <mesh filename="package://meshes/wheel4_omniwheel_tyre_v1.stl"/>
      </geometry>
    </collision>
  </link>
  <!-- Joint from wheel4_shaft_holder_v2_4 to wheel4_omniwheel_tyre_v1_79 -->
  <joint name="wheel_2b" type="continuous">
    <origin xyz="0.0237388 -0.0326737 0.0065" rpy="-2.51327 -1.5708 0"/>
    <parent link="wheel4_shaft_holder_v2_4"/>
    <child link="wheel4_omniwheel_tyre_v1_79"/>
    <axis xyz="0 0 1"/>
    <limit effort="5" velocity="10"/>
    <joint_properties friction="0.1"/>
  </joint>
  <!-- Link wheel4_omniwheel_tyre_v1_80 -->
  <link name="wheel4_omniwheel_tyre_v1_80">
    <inertial>
      <origin xyz="6.93633e-10 -2.72954e-18 1.35567e-09" rpy="0 0 0"/>
      <mass value="0.00502735"/>
      <inertia ixx="2.29535e-07" ixy="-9.00539e-29" ixz="-8.11134e-13" iyy="2.29535e-07" iyz="3.52823e-25" izz="2.32706e-07"/>
    </inertial>
    <!-- Part wheel4_omniwheel_tyre_v1_80 -->
    <visual>
      <origin xyz="0 0 0.01625" rpy="1.5708 7.62337e-17 3.14159"/>
      <geometry>
        <mesh filename="package://meshes/wheel4_omniwheel_tyre_v1.stl"/>
      </geometry>
      <material name="wheel4_omniwheel_tyre_v1_80_material">
        <color rgba="0.152941 0.152941 0.152941 1"/>
      </material>
    </visual>
    <collision>
      <origin xyz="0 0 0.01625" rpy="1.5708 7.62337e-17 3.14159"/>
      <geometry>
        <mesh filename="package://meshes/wheel4_omniwheel_tyre_v1.stl"/>
      </geometry>
    </collision>
  </link>
  <!-- Joint from wheel4_shaft_holder_v2_4 to wheel4_omniwheel_tyre_v1_80 -->
  <joint name="wheel_2a" type="continuous">
    <origin xyz="0.0384102 -0.0124802 0.0065" rpy="-1.25664 1.5708 0"/>
    <parent link="wheel4_shaft_holder_v2_4"/>
    <child link="wheel4_omniwheel_tyre_v1_80"/>
    <axis xyz="0 0 1"/>
    <limit effort="5" velocity="10"/>
    <joint_properties friction="0.1"/>
  </joint>
  <!-- Joint from part_1 to wheel4_shaft_holder_v2_4 -->
  <joint name="wheel_motorB" type="continuous">
    <origin xyz="0.105 -6.36065e-18 0.0125" rpy="3.14159 -1.5708 0"/>
    <parent link="part_1"/>
    <child link="wheel4_shaft_holder_v2_4"/>
    <axis xyz="0 0 1"/>
    <limit effort="5" velocity="10"/>
    <joint_properties friction="0.1"/>
  </joint>
</robot>
